Workbook

Sheet RATE MASTER
A1: PAPER RATE MASTER
A2: Yellow = update from vendor quotations. Grade codes start with 2-digit BF (e.g. 24GY, 25WTL, 14DUP). Blank grade = natural kraft (no suffix).
A4: Credit Cost % | B4: 0.015
A6: Grade Code | B6: Grade Description | C6: Paper Price (Rs/kg) | D6: Credit Cost (Rs/kg) | E6: Discount (Rs/kg) | F6: Incoming Freight (Rs/kg) | G6: Effective Rate (Rs/kg) | H6: Notes | K6: Threshold GSM | L6: GSM Condition | M6: Surcharge (Rs/kg) | N6: Basis | O6: Rule | P6: 0
A7: 16 | B7: 16 BF Kraft | C7: 31.5 | D7: =C7*$B$4 -> 0.4725 | E7: 1 | F7: 0 | G7: =C7+D7-E7+F7 -> 30.9725 | K7: 0 | L7: < 100 GSM | M7: 4 | N7: Per kg | O7: Thin paper handling premium
A8: 18 | B8: 18 BF Kraft | C8: 32 | D8: =C8*$B$4 -> 0.48 | E8: 1 | F8: 0 | G8: =C8+D8-E8+F8 -> 31.48 | K8: 100 | L8: Exactly 100 GSM | M8: 1.5 | N8: Per kg | O8: FIXED — any other value is an error of omission | P8: 0
A9: 20 | B9: 20 BF Kraft | C9: 33.5 | D9: =C9*$B$4 -> 0.5025 | E9: 1 | F9: 0 | G9: =C9+D9-E9+F9 -> 33.0025 | K9: 101 | L9: 101–200 GSM | M9: 0 | N9: Per kg | O9: No surcharge in this band | P9: 0
A10: 22 | B10: 22 BF Kraft | C10: 38 | D10: =C10*$B$4 -> 0.57 | E10: 1 | F10: 0 | G10: =C10+D10-E10+F10 -> 37.57 | K10: 201 | L10: > 200 GSM | M10: 1 | N10: Per kg | O10: Heavy paper handling premium | P10: 0
A11: 24 | B11: 24 BF Kraft | C11: 40 | D11: =C11*$B$4 -> 0.6 | E11: 1 | F11: 0 | G11: =C11+D11-E11+F11 -> 39.6 | H11: 25VK client spec → maps to 24GY. BF24/25 interchangeable; use 24.
A12: 25 | B12: 25 BF Kraft | C12: 41.25 | D12: =C12*$B$4 -> 0.61875 | E12: 1 | F12: 0 | G12: =C12+D12-E12+F12 -> 40.86875 | K12: Formula in CBB: =IFERROR(VLOOKUP(GSM,'RATE MASTER'!$A$26:$C$29,3,1),0). Surcharge added to Effective Rate per layer. 100 GSM surcharge = 1.5 is fixed — do not change.
A13: 28 | B13: 28 BF Kraft | C13: 43.5 | D13: =C13*$B$4 -> 0.6525 | E13: 1 | F13: 0 | G13: =C13+D13-E13+F13 -> 43.1525
A14: 35 | B14: 35 BF Kraft | C14: 51 | D14: =C14*$B$4 -> 0.765 | E14: 1 | F14: 0 | G14: =C14+D14-E14+F14 -> 50.765 | H14: Mills assure BF32. Use 33 in Calc BS. Values above 33 are bonus.
A15: 20GY | B15: 20 BF Golden Yellow (GY) | C15: 35 | D15: =C15*$B$4 -> 0.525 | E15: 1 | F15: 0 | G15: =C15+D15-E15+F15 -> 34.525
A16: 22GY | B16: 22 BF Golden Yellow (GY) | C16: 39.5 | D16: =C16*$B$4 -> 0.5925 | E16: 1 | F16: 0 | G16: =C16+D16-E16+F16 -> 39.0925
A17: 24GY | B17: 24 BF Golden Yellow (GY) | C17: 41.5 | D17: =C17*$B$4 -> 0.6225 | E17: 1 | F17: 0 | G17: =C17+D17-E17+F17 -> 41.1225 | H17: Maps to 25VK client spec.
A18: 28GY | B18: 28 BF Golden Yellow (GY) | C18: 44.5 | D18: =C18*$B$4 -> 0.6675 | E18: 1 | F18: 0 | G18: =C18+D18-E18+F18 -> 44.1675 | H18: Solar panel outer liners.
A19: 32GY | B19: 32 BF Golden Yellow (GY) | C19: 49 | D19: =C19*$B$4 -> 0.735 | E19: 1.5 | F19: 0 | G19: =C19+D19-E19+F19 -> 48.235
A20: 35GY | B20: 35 BF Golden Yellow (GY) | C20: 52 | D20: =C20*$B$4 -> 0.78 | E20: 1 | F20: 0 | G20: =C20+D20-E20+F20 -> 51.78 | H20: Use BF33 for Calc BS.
A21: 25WTL | B21: 25 BF White Top Liner (WTL) | C21: 76 | D21: =C21*$B$4 -> 1.14 | E21: 1 | F21: 0 | G21: =C21+D21-E21+F21 -> 76.14 | H21: Printable white top surface. Ice cream, bakery.
A22: 14DUP | B22: 14 BF Duplex Board | C22: 45 | D22: =C22*$B$4 -> 0.675 | E22: 1 | F22: 0 | G22: =C22+D22-E22+F22 -> 44.675 | H22: Offset/flexo printed boxes. Footwear inner, cold roll ice cream.
A23: 26HRCT | B23: 26 BF High Ring Crush Test Liner | C23: 44.5 | D23: =C23*$B$4 -> 0.6675 | E23: 1 | F23: 0 | G23: =C23+D23-E23+F23 -> 44.1675 | H23: Biscuits sector. Cost-optimised alternative.
A24: 40VKL | B24: 40 BF Imported Virgin Kraft Liner | C24: 68 | D24: =C24*$B$4 -> 1.02 | E24: 1 | F24: 0 | G24: =C24+D24-E24+F24 -> 68.02 | H24: Solar cell boxes. Longer lead time — flag in quotation.

Sheet DEFAULTS
A1: SECTOR DEFAULTS | M1: TAKE-UP FACTORS (for Calc GSM and Calc BS)
A2: Flute NOT sector-locked. Trim driven by Box Type table below. Take-up factors in separate table (cols M–Q). Sub-type notes omitted intentionally. | M2: Flute | N2: Rulebook Default | O2: Kolkata | P2: Nagpur | Q2: Pune | T2: Freight (Rs/kg) from Plant
M3: A | N3: 1.51 | O3: 1.51 | P3: 1.51 | Q3: 1.51 | S3: Delivery Location | T3: Kolkata | U3: Nagpur | V3: Pune
A4: Sector Code | B4: Sector Name | C4: Waste% CBB | D4: Waste% P&P | E4: Conv Rs/kg (box) | F4: Conv Rs/kg (P&P) | G4: Spec Language | H4: Dim Type | I4: Dim Unit | J4: Typical Box Type (ref only) | K4: Notes | M4: B | N4: 1.37 | O4: 1.35 | P4: 1.37 | Q4: 1.35 | S4: Nagpur | T4: 4 | U4: 2 | V4: 2
A5: PAINTS | B5: Paints / Decorative | C5: 5% | D5: 5% | E5: 7 | F5: 10 | G5: ECT+BS | H5: ID | I5: mm | J5: Die-R | K5: Die-based automated lines. Trim = client machine spec. | M5: C | N5: 1.47 | O5: 1.45 | P5: 1.47 | Q5: — | S5: Pune | T5: 4.2 | U5: 2.5 | V5: 1.8
A6: ALCOBEV-GL | B6: Alcobev — Glass Bottle | C6: 5% | D6: 3% | E6: 7 | F6: 10.5 | G6: BS | H6: ID | I6: mm | J6: RSC | K6: SET: RS4+Plate+2 Partitions. PP=B flute 18BF. 30-day,FCL,glued. | M6: E | N6: 1.31 | O6: 1.3 | P6: 1.31 | Q6: — | S6: Khed | T6: 3 | U6: 3 | V6: 3
A7: ALCOBEV-PET | B7: Alcobev — PET Bottle | C7: 5% | D7: 3% | E7: 7 | F7: 10.5 | G7: BS | H7: ID | I7: mm | J7: RSC | K7: SET: RS4+2 Plates+0 Partitions. Partition rows zeroed. | M7: Rulebook defaults (col N) confirmed from plant data. Plant 3 = 3rd plant for C flute only (1.48 — confirm exact value). Client-specified take-up (e.g. LT667 B=1.31/A=1.54) overrides in CBB layer columns. | S7: Kolkata | T7: 1.5 | U7: 4 | V7: 4.2
A8: ICE-CREAM | B8: Ice Cream / Dairy | C8: 5% | D8: 5% | E8: 12 | F8: 0 | G8: BS | H8: OD | I8: mm | J8: Die-S | K8: 10-day. E flute. Chemical coating option (~Rs 2/box). | S8: Haldia | T8: 2 | U8: 4.5 | V8: 4.5
A9: SOLAR-PANEL | B9: Solar — Panel Box | C9: 5% | D9: 3% | E9: 15 | F9: 0 | G9: BS+BCT | H9: ID | I9: mm | J9: HRSC-L | K9: SET: V Box+Base Sheet. Stitching count=client-specific. 30-day. | S9: Howrah | T9: 1.5 | U9: 4 | V9: 4.2
A10: SOLAR-CELL | B10: Solar — Cell/Ingot | C10: 5% | D10: 3% | E10: 6.5 | F10: 0 | G10: CS+BS | H10: ID | I10: mm | J10: RSC | K10: 40VKL option=longer lead time. | S10: Guwahati | T10: 3.5 | U10: 5.5 | V10: 5.5
A11: COOLER | B11: Coolers / White Goods | C11: 5% | D11: 0% | E11: 11 | F11: 0 | G11: BS | H11: ID | I11: mm | J11: HRSC-R | K11: 7-day. Confirm cutting trim formula (L+W+trim)×2 vs standard per client. | S11: Delhi | T11: 4 | U11: 3.5 | V11: 3.5
A12: TEXTILE | B12: Textiles / Warehousing | C12: 5% | D12: 0% | E12: 5.75 | F12: 0 | G12: BS | H12: ID | I12: mm | J12: RSC | K12: BC flute standard. No P&P. Lowest conversion in portfolio. | S12: Ahmedabad | T12: 5 | U12: 3 | V12: 2.5
A13: FOOD-SVC | B13: Food Service / QSR | C13: 5% | D13: 0% | E13: 12 | F13: 0 | G13: BCT | H13: ID | I13: mm | J13: Die-S | K13: ISO 22000 required. 25WTL top, VK inner, FG flute. 30-day. | S13: Hyderabad | T13: 4.5 | U13: 3.5 | V13: 3
A14: BISCUIT | B14: Biscuits & Confectionery | C14: 4% | D14: 5% | E14: 7 | F14: 10 | G14: BCT+BS | H14: ID | I14: mm | J14: RSC | K14: AlcoBev SET format: RS4+liner plate+U-liner. 26HRCT grade option.
A15: CHIPS | B15: Snacks / Chips | C15: 4% | D15: 5% | E15: 6.5 | F15: 10 | G15: BCT+BS | H15: ID | I15: mm | J15: RSC | K15: Sample vs Normal dual tier. BCT as MIN-text. Bid-period tender.
A16: PETROL | B16: Petroleum / Lubricants | C16: 5% | D16: 0% | E16: 7 | F16: 0 | G16: BCT+BS | H16: ID | I16: mm | J16: RSC | K16: Annual tender. Std vs Actual spec tracks. Volume in MT/year.
A17: EDIBLE-OIL | B17: FMCG / Edible Oils | C17: 5% | D17: 0% | E17: 7 | F17: 0 | G17: CS+BS | H17: ID | I17: mm | J17: RSC | K17: Seasonal paper spec: monsoon vs non-monsoon may differ.
A18: FOOTWEAR | B18: Footwear | C18: 5% | D18: 0% | E18: 8 | F18: 0 | G18: BS | H18: OD | I18: inch+mm | J18: Die-S | K18: Print type drives conv: SG=8, FFG=8.5, Offset=12.5.
A19: ELEC-LED | B19: Electronics / LED | C19: 6% | D19: 0% | E19: 7 | F19: 0 | G19: BS | H19: ID | I19: mm | J19: RSC | K19: 6% waste. A flute primary. 2-part stitched for >1200mm. | S19: Add more locations and rates as needed. CBB VLOOKUP uses Plant/Location column (col E) to auto-assign freight.
A20: BEAUTY | B20: Beauty / D2C | C20: 7% | D20: 0% | E20: 6 | F20: 0 | G20: BCT | H20: ID | I20: inch+mm | J20: Die-S | K20: 7% waste. Common deckle grouping. Multi-up (4 ups standard).
A21: CHEMICAL | B21: Chemicals / Adhesives | C21: 5% | D21: 5% | E21: 7 | F21: 0 | G21: BS | H21: OD | I21: mm | J21: RSC | K21: Cloth pasting option. Z-partition variant. GY grade standard.
A22: FANS | B22: Consumer Durables/Fans | C22: 5% | D22: 5% | E22: 8 | F22: 10 | G22: BS | H22: OD | I22: inch+mm | J22: RSC | K22: SET=Master box+Inner boxes+Plate. Inner costed separately.
A23: PHARMA | B23: Pharmaceuticals | C23: 5% | D23: 5% | E23: 7 | F23: 10 | G23: BCT+BS | H23: ID | I23: mm | J23: RSC | K23: GMP/regulatory compliance. Confirm spec language with client.
A24: FMCG-FOOD | B24: FMCG Food / Staples | C24: 5% | D24: 5% | E24: 7 | F24: 10 | G24: BCT+BS | H24: ID | I24: mm | J24: RSC | K24: Edible oils, pouch cartons, general food. Seasonal spec may apply.
A27: BOX TYPE TRIM DEFAULTS (3-ply Deckle → 3-ply Cutting → 5-ply Deckle → 5-ply Cutting)
A28: Code | B28: Box Type Name | C28: Deckle Formula | D28: Cutting Formula | E28: 3-ply Dkl (mm) | F28: 3-ply Cut (mm) | G28: 5-ply Dkl (mm) | H28: 5-ply Cut (mm) | I28: Gap/Up (mm) | J28: Industry Reference | K28: Notes
A29: RSC | B29: Regular Slotted Carton | C29: (W+H+10)×Ups+trim | D29: (L+W)×2+trim | E29: 30 | F29: 60 | G29: 35 | H29: 75 | I29: 10 | J29: Universal | K29: 10mm inter-blank gap per up for RSC. Trim: 30→60→35→75.
A30: HRSC-R | B30: Half-RSC Regular | C30: (W/2+H)×Ups+trim | D30: (L+W)×2+trim | E30: 30 | F30: 60 | G30: 35 | H30: 75 | I30: 0 | J30: Textile, coolers, WM/fridge (pending) | K30: No inter-blank gap. W/2 = one-sided flaps.
A31: HRSC-L | B31: Half-RSC Large (V Box) | C31: (W/2+H)×Ups+trim | D31: (L+W)×2+trim | E31: 55 | F31: 75 | G31: 55 | H31: 75 | I31: 0 | J31: Solar panel boxes (all clients) | K31: Large format. Accompanied by flat base sheet.
A32: HRSC-O | B32: Half-RSC Open (Sleeve) | C32: H×Ups+trim | D32: (L+W)×2+trim | E32: 15 | F32: 60 | G32: 15 | H32: 60 | I32: 0 | J32: Oil sleeve — Marico-type | K32: Open both ends. Deckle=H only.
A33: Die-S | B33: Die-cut Small | C33: (W+H)×Ups+trim | D33: (L+W)×2+trim | E33: 30 | F33: 45 | G33: 35 | H33: 50 | I33: 0 | J33: Ice cream, footwear inner, e-comm | K33: Confirm per client machine spec. No inter-blank gap.
A34: Die-R | B34: Die-cut Regular | C34: (W+H)×Ups+trim | D34: (L+W)×2+trim | E34: 44 | F34: 60 | G34: 60 | H34: 85 | I34: 0 | J34: Paints sector (Birla Opus, Asian Paints) | K34: Higher trim = automated erection line tolerance. Confirm per die layout.
A35: PP | B35: Plates & Partitions (P&P) | C35: F×Ups+trim | D35: G+trim | E35: 0 | F35: 0 | G35: 0 | H35: 0 | I35: 0 | J35: Alcobev, biscuits, paints, textile accessories | K35: Zero-trim P&P master (client-cut sheets). Dims formula-linked to parent Box row unless overridden by App input (F=L-5, G=W-5 for Plate).
A36: Board | B36: Board / Flat Sheet | C36: F×Ups+trim | D36: G+trim | E36: 10 | F36: 10 | G36: 10 | H36: 10 | I36: 0 | J36: Alcobev, biscuits, paints accessories | K36: Genuine flat-board box type (own trim margins, distinct from zero-trim PP master).
A37: Custom | B37: Custom / Non-standard | C37: Manual input | D37: Manual input | E37: — | F37: — | G37: — | H37: — | I37: 0 | J37: Specialized geometries | K37: Enter trim directly. Document die spec. Trim override enabled for Custom only.

Sheet CBB+PP
A1: CFB QUOTATION MASTER v7
A2: Client Plant: | C2: Client:
A3: Avadhoot Plant: | C3: Sector: | AY3: 0.035 | AZ3: → RS4 RATES | BA3: 6 | BB3: 0 | BC3: 0 | BD3: 0 | BE3: 0 | BF3: 0 | BG3: 0 | BH3: 0 | BI3: 0 | BJ3: 0.015 | BK3: =VLOOKUP(B2,DEFAULTS!$S$3:$V$20,IFERROR(MATCH($B$3,DEFAULTS!$T$3:$V$3,0)+1,2),0) -> #N/A | BL3: ← Interest: 0.5%=Prompt / 0.75%=Moderate / 1.0%=Delayed / 1.5%=Chronic | BM3: 0.02
A4: Date: | C4: Quote Ref: | U4: BCF | V4: 0.1 | AY4: 0.035 | AZ4: → BOARD RATES | BA4: 0 | BB4: 0 | BC4: 0 | BD4: 0 | BE4: 0 | BF4: 0 | BG4: 0 | BH4: 0 | BI4: 0 | BJ4: 0.015 | BL4: ← App Freight Override (Rs/kg): blank = auto from Plant×Location matrix (BH3 formula) | BM4: 0.02
A5: IDENTIFICATION | F5: DIMENSIONS (mm) | I5: BOX SETUP | L5: TRIM MARGINS (3-ply: Dkl→Cut | 5-ply: Dkl→Cut) | P5: CALC DIMS + AREA | S5: BOARD SPECIFICATION | AB5: FLUTES (A/B/C/E) | AD5: PAPER LAYERS — BF | GSM | AN5: RATES (Rs/kg + surcharge) | AS5: WEIGHTS (kg per box) | AZ5: COST BUILD-UP (Rs/box) ← Rates in rows 3 & 4 above → | BL5: TOTAL COST | BM5: MARGIN | BO5: FINAL RATE [MROUND 0.05] | BP5: Rs/kg | BQ5: MOQ
A6: Sr No (auto) | B6: Row Type | C6: Mat Code | D6: SKU / Description | E6: Plant / Location | F6: L (mm) | G6: W (mm) | H6: H (mm) | I6: Box Type | J6: PLY | K6: Ups | L6: 3-ply Dkl Trim | M6: 3-ply Cut Trim | N6: 5-ply Dkl Trim | O6: 5-ply Cut Trim | P6: DECKLE (mm) | Q6: CUTTING (mm) | R6: AREA (m²/box) | S6: Std GSM (Avg) | T6: Calc GSM (Avg) | U6: Std BS (NLT) | V6: Calc BS (kg/cm²) | W6: Std BCT (NLT kgf) | X6: Std ECT (NLT kN/m) | Y6: Std Cobb (Max g/m²) | Z6: Std Box Wt (g +-5%) | AA6: Est Box Wt (g) | AB6: F1 Flute | AC6: F2 Flute | AD6: TOP BF | AE6: TOP GSM | AF6: F1 BF | AG6: F1 GSM | AH6: L1 BF | AI6: L1 GSM | AJ6: F2 BF | AK6: F2 GSM | AL6: L2 BF | AM6: L2 GSM | AN6: Rate TOP | AO6: Rate F1 | AP6: Rate L1 | AQ6: Rate F2 | AR6: Rate L2 | AS6: Wt TOP (kg) | AT6: Wt F1 (kg) | AU6: Wt L1 (kg) | AV6: Wt F2 (kg) | AW6: Wt L2 (kg) | AX6: Paper Consumed (kg/box) | AY6: Sheet Wt_exWst (kg/box) | AZ6: Material Cost (Rs) | BA6: Conv Cost (Rs) | BB6: Printing (Rs) | BC6: Stitching (Rs) | BD6: Coating (Rs) | BE6: Non-Std Handling (Rs) | BF6: MOQ Charge (Rs) | BG6: Packing (Rs) | BH6: Other Cost (Rs) | BI6: Unloading (Rs) | BJ6: Interest (Rs) | BK6: Freight (Rs) | BL6: Total Cost (incl Freight) (Rs) | BM6: Margin % | BN6: Margin (Rs) | BO6: FINAL RATE (Rs/box) | BP6: Rate/kg (Rs) | BQ6: MOQ | BR6: SET Code | BS6: Nos/ Set | BT6: SET Rate Contribution (Rs/set)
A7: =IF(B7="","",IF(B7="Box",COUNTIF($B$7:B7,"Box"),TEXT(COUNTIF($B$7:B7,"Box"),"0")&IF(B7="Plate","a",IF(B7="Part-L","b",IF(B7="Part-W","c",""))))) -> 1 | B7: Box | L7: =IFERROR(INDEX(DEFAULTS!$E:$E,MATCH(I7,DEFAULTS!$A:$A,0)),"") | M7: =IFERROR(INDEX(DEFAULTS!$F:$F,MATCH(I7,DEFAULTS!$A:$A,0)),"") | N7: =IFERROR(INDEX(DEFAULTS!$G:$G,MATCH(I7,DEFAULTS!$A:$A,0)),"") | O7: =IFERROR(INDEX(DEFAULTS!$H:$H,MATCH(I7,DEFAULTS!$A:$A,0)),"") | P7: =IFERROR(IF(OR(I7="Board",I7="PP"),F7*K7+IF(J7=5,N7,L7),IF(I7="HRSC-L",(G7/2+H7)*K7+IF(J7=5,N7,L7),IF(I7="HRSC-R",(G7/2+H7)*K7+IF(J7=5,N7,L7),IF(I7="HRSC-O",H7*K7+IF(J7=5,N7,L7),(G7+H7)*K7+IF(J7=5,N7,L7))))),"") | Q7: =IFERROR(IF(OR(I7="Board",I7="PP"),G7+IF(J7=5,O7,M7),(F7+G7)*2+IF(J7=5,O7,M7)),"") | R7: =IFERROR(P7*Q7/1000000/K7,"") | T7: =IFERROR(AE7+AG7*IF(AB7="",1,IFERROR(VLOOKUP(AB7,DEFAULTS!$M$3:$Q$6,IFERROR(MATCH($B$3,DEFAULTS!$N$2:$Q$2,0)+1,2),0),1))+AI7+AK7*IF(AC7="",1,IFERROR(VLOOKUP(AC7,DEFAULTS!$M$3:$Q$6,IFERROR(MATCH($B$3,DEFAULTS!$N$2:$Q$2,0)+1,2),0),1))+AM7,"") -> 0 | V7: =IFERROR(IF(IFERROR(VALUE(LEFT(AD7,2)),0)=35,33,IFERROR(VALUE(LEFT(AD7,2)),0))*AE7/1000+IF(IFERROR(VALUE(LEFT(AF7,2)),0)=35,33,IFERROR(VALUE(LEFT(AF7,2)),0))*AG7*$V$4/1000+IF(IFERROR(VALUE(LEFT(AH7,2)),0)=35,33,IFERROR(VALUE(LEFT(AH7,2)),0))*AI7/1000+IF(IFERROR(VALUE(LEFT(AJ7,2)),0)=35,33,IFERROR(VALUE(LEFT(AJ7,2)),0))*AK7*$V$4/1000+IF(IFERROR(VALUE(LEFT(AL7,2)),0)=35,33,IFERROR(VALUE(LEFT(AL7,2)),0))*AM7/1000,"") -> 0 | AA7: =IFERROR(AY7*0.98*1000,0) -> 0 | AN7: =IFERROR(VLOOKUP(AD7,'RATE MASTER'!$A:$G,7,0)+IFERROR(VLOOKUP(AE7,'RATE MASTER'!$K$7:$M$10,3,1),0),"") | AO7: =IFERROR(VLOOKUP(AF7,'RATE MASTER'!$A:$G,7,0)+IFERROR(VLOOKUP(AG7,'RATE MASTER'!$K$7:$M$10,3,1),0),"") | AP7: =IFERROR(VLOOKUP(AH7,'RATE MASTER'!$A:$G,7,0)+IFERROR(VLOOKUP(AI7,'RATE MASTER'!$K$7:$M$10,3,1),0),"") | AQ7: =IFERROR(VLOOKUP(AJ7,'RATE MASTER'!$A:$G,7,0)+IFERROR(VLOOKUP(AK7,'RATE MASTER'!$K$7:$M$10,3,1),0),"") | AR7: =IFERROR(VLOOKUP(AL7,'RATE MASTER'!$A:$G,7,0)+IFERROR(VLOOKUP(AM7,'RATE MASTER'!$K$7:$M$10,3,1),0),"") | AS7: =IFERROR((AE7/1000)*R7*1*(1+IF(B7="Box",$AY$3,$AY$4)),0) -> 0 | AT7: =IFERROR((AG7/1000)*R7*IF(AB7="",1,IFERROR(VLOOKUP(AB7,DEFAULTS!$M$3:$Q$6,IFERROR(MATCH($B$3,DEFAULTS!$N$2:$Q$2,0)+1,2),0),1))*(1+IF(B7="Box",$AY$3,$AY$4)),0) -> 0 | AU7: =IFERROR((AI7/1000)*R7*1*(1+IF(B7="Box",$AY$3,$AY$4)),0) -> 0 | AV7: =IFERROR((AK7/1000)*R7*IF(AC7="",1,IFERROR(VLOOKUP(AC7,DEFAULTS!$M$3:$Q$6,IFERROR(MATCH($B$3,DEFAULTS!$N$2:$Q$2,0)+1,2),0),1))*(1+IF(B7="Box",$AY$3,$AY$4)),0) -> 0 | AW7: =IFERROR((AM7/1000)*R7*1*(1+IF(B7="Box",$AY$3,$AY$4)),0) -> 0 | AX7: =IFERROR(SUM(AS7:AW7),0) -> 0 | AY7: =IFERROR(AX7/(1+IF(B7="Box",$AY$3,$AY$4)),0) -> 0 | AZ7: =IFERROR(AS7*AN7+AT7*AO7+AU7*AP7+AV7*AQ7+AW7*AR7,0) -> 0 | BA7: =IFERROR(AX7*IF(B7="Box",$BA$3,$BA$4),0) -> 0 | BJ7: =IFERROR(SUM(AZ7:BI7)*$BJ$3,0) -> 0 | BK7: =IFERROR(AY7*IFERROR(IF($BK$4="",VLOOKUP(E7,DEFAULTS!$S$3:$V$20,IFERROR(MATCH($B$3,DEFAULTS!$T$3:$V$3,0)+1,2),0),$BK$4),0),0) -> 0 | BL7: =IFERROR(SUM(AZ7:BK7),0) -> 0 | BM7: =IFERROR(IF(B7="Box",$BM$3,$BM$4),0) -> 0.02 | BN7: =IFERROR(BL7*BM7,0) -> 0 | BO7: =IFERROR(MROUND(BL7+BN7,0.05),"") -> 0 | BP7: =IFERROR(BO7/AY7,"") | BQ7: =IFERROR(ROUND(J7*1100/AX7,-2),"") | BS7: =IF(B7="","",1) -> 1 | BT7: =IFERROR(MROUND(BO7*BS7,0.05),"") -> 0
A8: =IF(B8="","",IF(B8="Box",COUNTIF($B$7:B8,"Box"),TEXT(COUNTIF($B$7:B8,"Box"),"0")&IF(B8="Plate","a",IF(B8="Part-L","b",IF(B8="Part-W","c",""))))) | F8: =IF(OR(B8="",B8="Box"),"",IF(B8="Plate",IFERROR(LOOKUP(2,1/(B$7:B7="Box"),F$7:F7)-5,""),"")) | G8: =IF(OR(B8="",B8="Box"),"",IF(B8="Plate",IFERROR(LOOKUP(2,1/(B$7:B7="Box"),G$7:G7)-5,""),IF(OR(B8="Part-L",B8="Part-W"),IFERROR(LOOKUP(2,1/(B$7:B7="Box"),H$7:H7)-15,""),""))) | L8: =IFERROR(INDEX(DEFAULTS!$E:$E,MATCH(I8,DEFAULTS!$A:$A,0)),"") | M8: =IFERROR(INDEX(DEFAULTS!$F:$F,MATCH(I8,DEFAULTS!$A:$A,0)),"") | N8: =IFERROR(INDEX(DEFAULTS!$G:$G,MATCH(I8,DEFAULTS!$A:$A,0)),"") | O8: =IFERROR(INDEX(DEFAULTS!$H:$H,MATCH(I8,DEFAULTS!$A:$A,0)),"") | P8: =IFERROR(IF(OR(I8="Board",I8="PP"),F8*K8+IF(J8=5,N8,L8),IF(I8="HRSC-L",(G8/2+H8)*K8+IF(J8=5,N8,L8),IF(I8="HRSC-R",(G8/2+H8)*K8+IF(J8=5,N8,L8),IF(I8="HRSC-O",H8*K8+IF(J8=5,N8,L8),(G8+H8)*K8+IF(J8=5,N8,L8))))),"") | Q8: =IFERROR(IF(OR(I8="Board",I8="PP"),G8+IF(J8=5,O8,M8),(F8+G8)*2+IF(J8=5,O8,M8)),"") | R8: =IFERROR(P8*Q8/1000000/K8,"") | T8: =IFERROR(AE8+AG8*IF(AB8="",1,IFERROR(VLOOKUP(AB8,DEFAULTS!$M$3:$Q$6,IFERROR(MATCH($B$3,DEFAULTS!$N$2:$Q$2,0)+1,2),0),1))+AI8+AK8*IF(AC8="",1,IFERROR(VLOOKUP(AC8,DEFAULTS!$M$3:$Q$6,IFERROR(MATCH($B$3,DEFAULTS!$N$2:$Q$2,0)+1,2),0),1))+AM8,"") -> 0 | V8: =IFERROR(IF(IFERROR(VALUE(LEFT(AD8,2)),0)=35,33,IFERROR(VALUE(LEFT(AD8,2)),0))*AE8/1000+IF(IFERROR(VALUE(LEFT(AF8,2)),0)=35,33,IFERROR(VALUE(LEFT(AF8,2)),0))*AG8*$V$4/1000+IF(IFERROR(VALUE(LEFT(AH8,2)),0)=35,33,IFERROR(VALUE(LEFT(AH8,2)),0))*AI8/1000+IF(IFERROR(VALUE(LEFT(AJ8,2)),0)=35,33,IFERROR(VALUE(LEFT(AJ8,2)),0))*AK8*$V$4/1000+IF(IFERROR(VALUE(LEFT(AL8,2)),0)=35,33,IFERROR(VALUE(LEFT(AL8,2)),0))*AM8/1000,"") -> 0 | AA8: =IFERROR(AY8*0.98*1000,0) -> 0 | AN8: =IFERROR(VLOOKUP(AD8,'RATE MASTER'!$A:$G,7,0)+IFERROR(VLOOKUP(AE8,'RATE MASTER'!$K$7:$M$10,3,1),0),"") | AO8: =IFERROR(VLOOKUP(AF8,'RATE MASTER'!$A:$G,7,0)+IFERROR(VLOOKUP(AG8,'RATE MASTER'!$K$7:$M$10,3,1),0),"") | AP8: =IFERROR(VLOOKUP(AH8,'RATE MASTER'!$A:$G,7,0)+IFERROR(VLOOKUP(AI8,'RATE MASTER'!$K$7:$M$10,3,1),0),"") | AQ8: =IFERROR(VLOOKUP(AJ8,'RATE MASTER'!$A:$G,7,0)+IFERROR(VLOOKUP(AK8,'RATE MASTER'!$K$7:$M$10,3,1),0),"") | AR8: =IFERROR(VLOOKUP(AL8,'RATE MASTER'!$A:$G,7,0)+IFERROR(VLOOKUP(AM8,'RATE MASTER'!$K$7:$M$10,3,1),0),"") | AS8: =IFERROR((AE8/1000)*R8*1*(1+IF(B8="Box",$AY$3,$AY$4)),0) -> 0 | AT8: =IFERROR((AG8/1000)*R8*IF(AB8="",1,IFERROR(VLOOKUP(AB8,DEFAULTS!$M$3:$Q$6,IFERROR(MATCH($B$3,DEFAULTS!$N$2:$Q$2,0)+1,2),0),1))*(1+IF(B8="Box",$AY$3,$AY$4)),0) -> 0 | AU8: =IFERROR((AI8/1000)*R8*1*(1+IF(B8="Box",$AY$3,$AY$4)),0) -> 0 | AV8: =IFERROR((AK8/1000)*R8*IF(AC8="",1,IFERROR(VLOOKUP(AC8,DEFAULTS!$M$3:$Q$6,IFERROR(MATCH($B$3,DEFAULTS!$N$2:$Q$2,0)+1,2),0),1))*(1+IF(B8="Box",$AY$3,$AY$4)),0) -> 0 | AW8: =IFERROR((AM8/1000)*R8*1*(1+IF(B8="Box",$AY$3,$AY$4)),0) -> 0 | AX8: =IFERROR(SUM(AS8:AW8),0) -> 0 | AY8: =IFERROR(AX8/(1+IF(B8="Box",$AY$3,$AY$4)),0) -> 0 | AZ8: =IFERROR(AS8*AN8+AT8*AO8+AU8*AP8+AV8*AQ8+AW8*AR8,0) -> 0 | BA8: =IFERROR(AX8*IF(B8="Box",$BA$3,$BA$4),0) -> 0 | BJ8: =IFERROR(SUM(AZ8:BI8)*$BJ$3,0) -> 0 | BK8: =IFERROR(AY8*IFERROR(IF($BK$4="",VLOOKUP(E8,DEFAULTS!$S$3:$V$20,IFERROR(MATCH($B$3,DEFAULTS!$T$3:$V$3,0)+1,2),0),$BK$4),0),0) -> 0 | BL8: =IFERROR(SUM(AZ8:BK8),0) -> 0 | BM8: =IFERROR(IF(B8="Box",$BM$3,$BM$4),0) -> 0.02 | BN8: =IFERROR(BL8*BM8,0) -> 0 | BO8: =IFERROR(MROUND(BL8+BN8,0.05),"") -> 0 | BP8: =IFERROR(BO8/AY8,"") | BQ8: =IFERROR(ROUND(J8*1100/AX8,-2),"") | BS8: =IF(B8="","",1) | BT8: =IFERROR(MROUND(BO8*BS8,0.05),"")
A9: =IF(B9="","",IF(B9="Box",COUNTIF($B$7:B9,"Box"),TEXT(COUNTIF($B$7:B9,"Box"),"0")&IF(B9="Plate","a",IF(B9="Part-L","b",IF(B9="Part-W","c",""))))) | F9: =IF(OR(B9="",B9="Box"),"",IF(B9="Plate",IFERROR(LOOKUP(2,1/(B$7:B8="Box"),F$7:F8)-5,""),"")) | G9: =IF(OR(B9="",B9="Box"),"",IF(B9="Plate",IFERROR(LOOKUP(2,1/(B$7:B8="Box"),G$7:G8)-5,""),IF(OR(B9="Part-L",B9="Part-W"),IFERROR(LOOKUP(2,1/(B$7:B8="Box"),H$7:H8)-15,""),""))) | L9: =IFERROR(INDEX(DEFAULTS!$E:$E,MATCH(I9,DEFAULTS!$A:$A,0)),"") | M9: =IFERROR(INDEX(DEFAULTS!$F:$F,MATCH(I9,DEFAULTS!$A:$A,0)),"") | N9: =IFERROR(INDEX(DEFAULTS!$G:$G,MATCH(I9,DEFAULTS!$A:$A,0)),"") | O9: =IFERROR(INDEX(DEFAULTS!$H:$H,MATCH(I9,DEFAULTS!$A:$A,0)),"") | P9: =IFERROR(IF(OR(I9="Board",I9="PP"),F9*K9+IF(J9=5,N9,L9),IF(I9="HRSC-L",(G9/2+H9)*K9+IF(J9=5,N9,L9),IF(I9="HRSC-R",(G9/2+H9)*K9+IF(J9=5,N9,L9),IF(I9="HRSC-O",H9*K9+IF(J9=5,N9,L9),(G9+H9)*K9+IF(J9=5,N9,L9))))),"") | Q9: =IFERROR(IF(OR(I9="Board",I9="PP"),G9+IF(J9=5,O9,M9),(F9+G9)*2+IF(J9=5,O9,M9)),"") | R9: =IFERROR(P9*Q9/1000000/K9,"") | T9: =IFERROR(AE9+AG9*IF(AB9="",1,IFERROR(VLOOKUP(AB9,DEFAULTS!$M$3:$Q$6,IFERROR(MATCH($B$3,DEFAULTS!$N$2:$Q$2,0)+1,2),0),1))+AI9+AK9*IF(AC9="",1,IFERROR(VLOOKUP(AC9,DEFAULTS!$M$3:$Q$6,IFERROR(MATCH($B$3,DEFAULTS!$N$2:$Q$2,0)+1,2),0),1))+AM9,"") -> 0 | V9: =IFERROR(IF(IFERROR(VALUE(LEFT(AD9,2)),0)=35,33,IFERROR(VALUE(LEFT(AD9,2)),0))*AE9/1000+IF(IFERROR(VALUE(LEFT(AF9,2)),0)=35,33,IFERROR(VALUE(LEFT(AF9,2)),0))*AG9*$V$4/1000+IF(IFERROR(VALUE(LEFT(AH9,2)),0)=35,33,IFERROR(VALUE(LEFT(AH9,2)),0))*AI9/1000+IF(IFERROR(VALUE(LEFT(AJ9,2)),0)=35,33,IFERROR(VALUE(LEFT(AJ9,2)),0))*AK9*$V$4/1000+IF(IFERROR(VALUE(LEFT(AL9,2)),0)=35,33,IFERROR(VALUE(LEFT(AL9,2)),0))*AM9/1000,"") -> 0 | AA9: =IFERROR(AY9*0.98*1000,0) -> 0 | AN9: =IFERROR(VLOOKUP(AD9,'RATE MASTER'!$A:$G,7,0)+IFERROR(VLOOKUP(AE9,'RATE MASTER'!$K$7:$M$10,3,1),0),"") | AO9: =IFERROR(VLOOKUP(AF9,'RATE MASTER'!$A:$G,7,0)+IFERROR(VLOOKUP(AG9,'RATE MASTER'!$K$7:$M$10,3,1),0),"") | AP9: =IFERROR(VLOOKUP(AH9,'RATE MASTER'!$A:$G,7,0)+IFERROR(VLOOKUP(AI9,'RATE MASTER'!$K$7:$M$10,3,1),0),"") | AQ9: =IFERROR(VLOOKUP(AJ9,'RATE MASTER'!$A:$G,7,0)+IFERROR(VLOOKUP(AK9,'RATE MASTER'!$K$7:$M$10,3,1),0),"") | AR9: =IFERROR(VLOOKUP(AL9,'RATE MASTER'!$A:$G,7,0)+IFERROR(VLOOKUP(AM9,'RATE MASTER'!$K$7:$M$10,3,1),0),"") | AS9: =IFERROR((AE9/1000)*R9*1*(1+IF(B9="Box",$AY$3,$AY$4)),0) -> 0 | AT9: =IFERROR((AG9/1000)*R9*IF(AB9="",1,IFERROR(VLOOKUP(AB9,DEFAULTS!$M$3:$Q$6,IFERROR(MATCH($B$3,DEFAULTS!$N$2:$Q$2,0)+1,2),0),1))*(1+IF(B9="Box",$AY$3,$AY$4)),0) -> 0 | AU9: =IFERROR((AI9/1000)*R9*1*(1+IF(B9="Box",$AY$3,$AY$4)),0) -> 0 | AV9: =IFERROR((AK9/1000)*R9*IF(AC9="",1,IFERROR(VLOOKUP(AC9,DEFAULTS!$M$3:$Q$6,IFERROR(MATCH($B$3,DEFAULTS!$N$2:$Q$2,0)+1,2),0),1))*(1+IF(B9="Box",$AY$3,$AY$4)),0) -> 0 | AW9: =IFERROR((AM9/1000)*R9*1*(1+IF(B9="Box",$AY$3,$AY$4)),0) -> 0 | AX9: =IFERROR(SUM(AS9:AW9),0) -> 0 | AY9: =IFERROR(AX9/(1+IF(B9="Box",$AY$3,$AY$4)),0) -> 0 | AZ9: =IFERROR(AS9*AN9+AT9*AO9+AU9*AP9+AV9*AQ9+AW9*AR9,0) -> 0 | BA9: =IFERROR(AX9*IF(B9="Box",$BA$3,$BA$4),0) -> 0 | BJ9: =IFERROR(SUM(AZ9:BI9)*$BJ$3,0) -> 0 | BK9: =IFERROR(AY9*IFERROR(IF($BK$4="",VLOOKUP(E9,DEFAULTS!$S$3:$V$20,IFERROR(MATCH($B$3,DEFAULTS!$T$3:$V$3,0)+1,2),0),$BK$4),0),0) -> 0 | BL9: =IFERROR(SUM(AZ9:BK9),0) -> 0 | BM9: =IFERROR(IF(B9="Box",$BM$3,$BM$4),0) -> 0.02 | BN9: =IFERROR(BL9*BM9,0) -> 0 | BO9: =IFERROR(MROUND(BL9+BN9,0.05),"") -> 0 | BP9: =IFERROR(BO9/AY9,"") | BQ9: =IFERROR(ROUND(J9*1100/AX9,-2),"") | BS9: =IF(B9="","",1) | BT9: =IFERROR(MROUND(BO9*BS9,0.05),"")
A10: =IF(B10="","",IF(B10="Box",COUNTIF($B$7:B10,"Box"),TEXT(COUNTIF($B$7:B10,"Box"),"0")&IF(B10="Plate","a",IF(B10="Part-L","b",IF(B10="Part-W","c",""))))) | F10: =IF(OR(B10="",B10="Box"),"",IF(B10="Plate",IFERROR(LOOKUP(2,1/(B$7:B9="Box"),F$7:F9)-5,""),"")) | G10: =IF(OR(B10="",B10="Box"),"",IF(B10="Plate",IFERROR(LOOKUP(2,1/(B$7:B9="Box"),G$7:G9)-5,""),IF(OR(B10="Part-L",B10="Part-W"),IFERROR(LOOKUP(2,1/(B$7:B9="Box"),H$7:H9)-15,""),""))) | L10: =IFERROR(INDEX(DEFAULTS!$E:$E,MATCH(I10,DEFAULTS!$A:$A,0)),"") | M10: =IFERROR(INDEX(DEFAULTS!$F:$F,MATCH(I10,DEFAULTS!$A:$A,0)),"") | N10: =IFERROR(INDEX(DEFAULTS!$G:$G,MATCH(I10,DEFAULTS!$A:$A,0)),"") | O10: =IFERROR(INDEX(DEFAULTS!$H:$H,MATCH(I10,DEFAULTS!$A:$A,0)),"") | P10: =IFERROR(IF(OR(I10="Board",I10="PP"),F10*K10+IF(J10=5,N10,L10),IF(I10="HRSC-L",(G10/2+H10)*K10+IF(J10=5,N10,L10),IF(I10="HRSC-R",(G10/2+H10)*K10+IF(J10=5,N10,L10),IF(I10="HRSC-O",H10*K10+IF(J10=5,N10,L10),(G10+H10)*K10+IF(J10=5,N10,L10))))),"") | Q10: =IFERROR(IF(OR(I10="Board",I10="PP"),G10+IF(J10=5,O10,M10),(F10+G10)*2+IF(J10=5,O10,M10)),"") | R10: =IFERROR(P10*Q10/1000000/K10,"") | T10: =IFERROR(AE10+AG10*IF(AB10="",1,IFERROR(VLOOKUP(AB10,DEFAULTS!$M$3:$Q$6,IFERROR(MATCH($B$3,DEFAULTS!$N$2:$Q$2,0)+1,2),0),1))+AI10+AK10*IF(AC10="",1,IFERROR(VLOOKUP(AC10,DEFAULTS!$M$3:$Q$6,IFERROR(MATCH($B$3,DEFAULTS!$N$2:$Q$2,0)+1,2),0),1))+AM10,"") -> 0 | V10: =IFERROR(IF(IFERROR(VALUE(LEFT(AD10,2)),0)=35,33,IFERROR(VALUE(LEFT(AD10,2)),0))*AE10/1000+IF(IFERROR(VALUE(LEFT(AF10,2)),0)=35,33,IFERROR(VALUE(LEFT(AF10,2)),0))*AG10*$V$4/1000+IF(IFERROR(VALUE(LEFT(AH10,2)),0)=35,33,IFERROR(VALUE(LEFT(AH10,2)),0))*AI10/1000+IF(IFERROR(VALUE(LEFT(AJ10,2)),0)=35,33,IFERROR(VALUE(LEFT(AJ10,2)),0))*AK10*$V$4/1000+IF(IFERROR(VALUE(LEFT(AL10,2)),0)=35,33,IFERROR(VALUE(LEFT(AL10,2)),0))*AM10/1000,"") -> 0 | AA10: =IFERROR(AY10*0.98*1000,0) -> 0 | AN10: =IFERROR(VLOOKUP(AD10,'RATE MASTER'!$A:$G,7,0)+IFERROR(VLOOKUP(AE10,'RATE MASTER'!$K$7:$M$10,3,1),0),"") | AO10: =IFERROR(VLOOKUP(AF10,'RATE MASTER'!$A:$G,7,0)+IFERROR(VLOOKUP(AG10,'RATE MASTER'!$K$7:$M$10,3,1),0),"") | AP10: =IFERROR(VLOOKUP(AH10,'RATE MASTER'!$A:$G,7,0)+IFERROR(VLOOKUP(AI10,'RATE MASTER'!$K$7:$M$10,3,1),0),"") | AQ10: =IFERROR(VLOOKUP(AJ10,'RATE MASTER'!$A:$G,7,0)+IFERROR(VLOOKUP(AK10,'RATE MASTER'!$K$7:$M$10,3,1),0),"") | AR10: =IFERROR(VLOOKUP(AL10,'RATE MASTER'!$A:$G,7,0)+IFERROR(VLOOKUP(AM10,'RATE MASTER'!$K$7:$M$10,3,1),0),"") | AS10: =IFERROR((AE10/1000)*R10*1*(1+IF(B10="Box",$AY$3,$AY$4)),0) -> 0 | AT10: =IFERROR((AG10/1000)*R10*IF(AB10="",1,IFERROR(VLOOKUP(AB10,DEFAULTS!$M$3:$Q$6,IFERROR(MATCH($B$3,DEFAULTS!$N$2:$Q$2,0)+1,2),0),1))*(1+IF(B10="Box",$AY$3,$AY$4)),0) -> 0 | AU10: =IFERROR((AI10/1000)*R10*1*(1+IF(B10="Box",$AY$3,$AY$4)),0) -> 0 | AV10: =IFERROR((AK10/1000)*R10*IF(AC10="",1,IFERROR(VLOOKUP(AC10,DEFAULTS!$M$3:$Q$6,IFERROR(MATCH($B$3,DEFAULTS!$N$2:$Q$2,0)+1,2),0),1))*(1+IF(B10="Box",$AY$3,$AY$4)),0) -> 0 | AW10: =IFERROR((AM10/1000)*R10*1*(1+IF(B10="Box",$AY$3,$AY$4)),0) -> 0 | AX10: =IFERROR(SUM(AS10:AW10),0) -> 0 | AY10: =IFERROR(AX10/(1+IF(B10="Box",$AY$3,$AY$4)),0) -> 0 | AZ10: =IFERROR(AS10*AN10+AT10*AO10+AU10*AP10+AV10*AQ10+AW10*AR10,0) -> 0 | BA10: =IFERROR(AX10*IF(B10="Box",$BA$3,$BA$4),0) -> 0 | BJ10: =IFERROR(SUM(AZ10:BI10)*$BJ$3,0) -> 0 | BK10: =IFERROR(AY10*IFERROR(IF($BK$4="",VLOOKUP(E10,DEFAULTS!$S$3:$V$20,IFERROR(MATCH($B$3,DEFAULTS!$T$3:$V$3,0)+1,2),0),$BK$4),0),0) -> 0 | BL10: =IFERROR(SUM(AZ10:BK10),0) -> 0 | BM10: =IFERROR(IF(B10="Box",$BM$3,$BM$4),0) -> 0.02 | BN10: =IFERROR(BL10*BM10,0) -> 0 | BO10: =IFERROR(MROUND(BL10+BN10,0.05),"") -> 0 | BP10: =IFERROR(BO10/AY10,"") | BQ10: =IFERROR(ROUND(J10*1100/AX10,-2),"") | BS10: =IF(B10="","",1) | BT10: =IFERROR(MROUND(BO10*BS10,0.05),"")
A11: =IF(B11="","",IF(B11="Box",COUNTIF($B$7:B11,"Box"),TEXT(COUNTIF($B$7:B11,"Box"),"0")&IF(B11="Plate","a",IF(B11="Part-L","b",IF(B11="Part-W","c",""))))) | F11: =IF(OR(B11="",B11="Box"),"",IF(B11="Plate",IFERROR(LOOKUP(2,1/(B$7:B10="Box"),F$7:F10)-5,""),"")) | G11: =IF(OR(B11="",B11="Box"),"",IF(B11="Plate",IFERROR(LOOKUP(2,1/(B$7:B10="Box"),G$7:G10)-5,""),IF(OR(B11="Part-L",B11="Part-W"),IFERROR(LOOKUP(2,1/(B$7:B10="Box"),H$7:H10)-15,""),""))) | L11: =IFERROR(INDEX(DEFAULTS!$E:$E,MATCH(I11,DEFAULTS!$A:$A,0)),"") | M11: =IFERROR(INDEX(DEFAULTS!$F:$F,MATCH(I11,DEFAULTS!$A:$A,0)),"") | N11: =IFERROR(INDEX(DEFAULTS!$G:$G,MATCH(I11,DEFAULTS!$A:$A,0)),"") | O11: =IFERROR(INDEX(DEFAULTS!$H:$H,MATCH(I11,DEFAULTS!$A:$A,0)),"") | P11: =IFERROR(IF(OR(I11="Board",I11="PP"),F11*K11+IF(J11=5,N11,L11),IF(I11="HRSC-L",(G11/2+H11)*K11+IF(J11=5,N11,L11),IF(I11="HRSC-R",(G11/2+H11)*K11+IF(J11=5,N11,L11),IF(I11="HRSC-O",H11*K11+IF(J11=5,N11,L11),(G11+H11)*K11+IF(J11=5,N11,L11))))),"") | Q11: =IFERROR(IF(OR(I11="Board",I11="PP"),G11+IF(J11=5,O11,M11),(F11+G11)*2+IF(J11=5,O11,M11)),"") | R11: =IFERROR(P11*Q11/1000000/K11,"") | T11: =IFERROR(AE11+AG11*IF(AB11="",1,IFERROR(VLOOKUP(AB11,DEFAULTS!$M$3:$Q$6,IFERROR(MATCH($B$3,DEFAULTS!$N$2:$Q$2,0)+1,2),0),1))+AI11+AK11*IF(AC11="",1,IFERROR(VLOOKUP(AC11,DEFAULTS!$M$3:$Q$6,IFERROR(MATCH($B$3,DEFAULTS!$N$2:$Q$2,0)+1,2),0),1))+AM11,"") -> 0 | V11: =IFERROR(IF(IFERROR(VALUE(LEFT(AD11,2)),0)=35,33,IFERROR(VALUE(LEFT(AD11,2)),0))*AE11/1000+IF(IFERROR(VALUE(LEFT(AF11,2)),0)=35,33,IFERROR(VALUE(LEFT(AF11,2)),0))*AG11*$V$4/1000+IF(IFERROR(VALUE(LEFT(AH11,2)),0)=35,33,IFERROR(VALUE(LEFT(AH11,2)),0))*AI11/1000+IF(IFERROR(VALUE(LEFT(AJ11,2)),0)=35,33,IFERROR(VALUE(LEFT(AJ11,2)),0))*AK11*$V$4/1000+IF(IFERROR(VALUE(LEFT(AL11,2)),0)=35,33,IFERROR(VALUE(LEFT(AL11,2)),0))*AM11/1000,"") -> 0 | AA11: =IFERROR(AY11*0.98*1000,0) -> 0 | AN11: =IFERROR(VLOOKUP(AD11,'RATE MASTER'!$A:$G,7,0)+IFERROR(VLOOKUP(AE11,'RATE MASTER'!$K$7:$M$10,3,1),0),"") | AO11: =IFERROR(VLOOKUP(AF11,'RATE MASTER'!$A:$G,7,0)+IFERROR(VLOOKUP(AG11,'RATE MASTER'!$K$7:$M$10,3,1),0),"") | AP11: =IFERROR(VLOOKUP(AH11,'RATE MASTER'!$A:$G,7,0)+IFERROR(VLOOKUP(AI11,'RATE MASTER'!$K$7:$M$10,3,1),0),"") | AQ11: =IFERROR(VLOOKUP(AJ11,'RATE MASTER'!$A:$G,7,0)+IFERROR(VLOOKUP(AK11,'RATE MASTER'!$K$7:$M$10,3,1),0),"") | AR11: =IFERROR(VLOOKUP(AL11,'RATE MASTER'!$A:$G,7,0)+IFERROR(VLOOKUP(AM11,'RATE MASTER'!$K$7:$M$10,3,1),0),"") | AS11: =IFERROR((AE11/1000)*R11*1*(1+IF(B11="Box",$AY$3,$AY$4)),0) -> 0 | AT11: =IFERROR((AG11/1000)*R11*IF(AB11="",1,IFERROR(VLOOKUP(AB11,DEFAULTS!$M$3:$Q$6,IFERROR(MATCH($B$3,DEFAULTS!$N$2:$Q$2,0)+1,2),0),1))*(1+IF(B11="Box",$AY$3,$AY$4)),0) -> 0 | AU11: =IFERROR((AI11/1000)*R11*1*(1+IF(B11="Box",$AY$3,$AY$4)),0) -> 0 | AV11: =IFERROR((AK11/1000)*R11*IF(AC11="",1,IFERROR(VLOOKUP(AC11,DEFAULTS!$M$3:$Q$6,IFERROR(MATCH($B$3,DEFAULTS!$N$2:$Q$2,0)+1,2),0),1))*(1+IF(B11="Box",$AY$3,$AY$4)),0) -> 0 | AW11: =IFERROR((AM11/1000)*R11*1*(1+IF(B11="Box",$AY$3,$AY$4)),0) -> 0 | AX11: =IFERROR(SUM(AS11:AW11),0) -> 0 | AY11: =IFERROR(AX11/(1+IF(B11="Box",$AY$3,$AY$4)),0) -> 0 | AZ11: =IFERROR(AS11*AN11+AT11*AO11+AU11*AP11+AV11*AQ11+AW11*AR11,0) -> 0 | BA11: =IFERROR(AX11*IF(B11="Box",$BA$3,$BA$4),0) -> 0 | BJ11: =IFERROR(SUM(AZ11:BI11)*$BJ$3,0) -> 0 | BK11: =IFERROR(AY11*IFERROR(IF($BK$4="",VLOOKUP(E11,DEFAULTS!$S$3:$V$20,IFERROR(MATCH($B$3,DEFAULTS!$T$3:$V$3,0)+1,2),0),$BK$4),0),0) -> 0 | BL11: =IFERROR(SUM(AZ11:BK11),0) -> 0 | BM11: =IFERROR(IF(B11="Box",$BM$3,$BM$4),0) -> 0.02 | BN11: =IFERROR(BL11*BM11,0) -> 0 | BO11: =IFERROR(MROUND(BL11+BN11,0.05),"") -> 0 | BP11: =IFERROR(BO11/AY11,"") | BQ11: =IFERROR(ROUND(J11*1100/AX11,-2),"") | BS11: =IF(B11="","",1) | BT11: =IFERROR(MROUND(BO11*BS11,0.05),"")
A12: =IF(B12="","",IF(B12="Box",COUNTIF($B$7:B12,"Box"),TEXT(COUNTIF($B$7:B12,"Box"),"0")&IF(B12="Plate","a",IF(B12="Part-L","b",IF(B12="Part-W","c",""))))) | F12: =IF(OR(B12="",B12="Box"),"",IF(B12="Plate",IFERROR(LOOKUP(2,1/(B$7:B11="Box"),F$7:F11)-5,""),"")) | G12: =IF(OR(B12="",B12="Box"),"",IF(B12="Plate",IFERROR(LOOKUP(2,1/(B$7:B11="Box"),G$7:G11)-5,""),IF(OR(B12="Part-L",B12="Part-W"),IFERROR(LOOKUP(2,1/(B$7:B11="Box"),H$7:H11)-15,""),""))) | L12: =IFERROR(INDEX(DEFAULTS!$E:$E,MATCH(I12,DEFAULTS!$A:$A,0)),"") | M12: =IFERROR(INDEX(DEFAULTS!$F:$F,MATCH(I12,DEFAULTS!$A:$A,0)),"") | N12: =IFERROR(INDEX(DEFAULTS!$G:$G,MATCH(I12,DEFAULTS!$A:$A,0)),"") | O12: =IFERROR(INDEX(DEFAULTS!$H:$H,MATCH(I12,DEFAULTS!$A:$A,0)),"") | P12: =IFERROR(IF(OR(I12="Board",I12="PP"),F12*K12+IF(J12=5,N12,L12),IF(I12="HRSC-L",(G12/2+H12)*K12+IF(J12=5,N12,L12),IF(I12="HRSC-R",(G12/2+H12)*K12+IF(J12=5,N12,L12),IF(I12="HRSC-O",H12*K12+IF(J12=5,N12,L12),(G12+H12)*K12+IF(J12=5,N12,L12))))),"") | Q12: =IFERROR(IF(OR(I12="Board",I12="PP"),G12+IF(J12=5,O12,M12),(F12+G12)*2+IF(J12=5,O12,M12)),"") | R12: =IFERROR(P12*Q12/1000000/K12,"") | T12: =IFERROR(AE12+AG12*IF(AB12="",1,IFERROR(VLOOKUP(AB12,DEFAULTS!$M$3:$Q$6,IFERROR(MATCH($B$3,DEFAULTS!$N$2:$Q$2,0)+1,2),0),1))+AI12+AK12*IF(AC12="",1,IFERROR(VLOOKUP(AC12,DEFAULTS!$M$3:$Q$6,IFERROR(MATCH($B$3,DEFAULTS!$N$2:$Q$2,0)+1,2),0),1))+AM12,"") -> 0 | V12: =IFERROR(IF(IFERROR(VALUE(LEFT(AD12,2)),0)=35,33,IFERROR(VALUE(LEFT(AD12,2)),0))*AE12/1000+IF(IFERROR(VALUE(LEFT(AF12,2)),0)=35,33,IFERROR(VALUE(LEFT(AF12,2)),0))*AG12*$V$4/1000+IF(IFERROR(VALUE(LEFT(AH12,2)),0)=35,33,IFERROR(VALUE(LEFT(AH12,2)),0))*AI12/1000+IF(IFERROR(VALUE(LEFT(AJ12,2)),0)=35,33,IFERROR(VALUE(LEFT(AJ12,2)),0))*AK12*$V$4/1000+IF(IFERROR(VALUE(LEFT(AL12,2)),0)=35,33,IFERROR(VALUE(LEFT(AL12,2)),0))*AM12/1000,"") -> 0 | AA12: =IFERROR(AY12*0.98*1000,0) -> 0 | AN12: =IFERROR(VLOOKUP(AD12,'RATE MASTER'!$A:$G,7,0)+IFERROR(VLOOKUP(AE12,'RATE MASTER'!$K$7:$M$10,3,1),0),"") | AO12: =IFERROR(VLOOKUP(AF12,'RATE MASTER'!$A:$G,7,0)+IFERROR(VLOOKUP(AG12,'RATE MASTER'!$K$7:$M$10,3,1),0),"") | AP12: =IFERROR(VLOOKUP(AH12,'RATE MASTER'!$A:$G,7,0)+IFERROR(VLOOKUP(AI12,'RATE MASTER'!$K$7:$M$10,3,1),0),"") | AQ12: =IFERROR(VLOOKUP(AJ12,'RATE MASTER'!$A:$G,7,0)+IFERROR(VLOOKUP(AK12,'RATE MASTER'!$K$7:$M$10,3,1),0),"") | AR12: =IFERROR(VLOOKUP(AL12,'RATE MASTER'!$A:$G,7,0)+IFERROR(VLOOKUP(AM12,'RATE MASTER'!$K$7:$M$10,3,1),0),"") | AS12: =IFERROR((AE12/1000)*R12*1*(1+IF(B12="Box",$AY$3,$AY$4)),0) -> 0 | AT12: =IFERROR((AG12/1000)*R12*IF(AB12="",1,IFERROR(VLOOKUP(AB12,DEFAULTS!$M$3:$Q$6,IFERROR(MATCH($B$3,DEFAULTS!$N$2:$Q$2,0)+1,2),0),1))*(1+IF(B12="Box",$AY$3,$AY$4)),0) -> 0 | AU12: =IFERROR((AI12/1000)*R12*1*(1+IF(B12="Box",$AY$3,$AY$4)),0) -> 0 | AV12: =IFERROR((AK12/1000)*R12*IF(AC12="",1,IFERROR(VLOOKUP(AC12,DEFAULTS!$M$3:$Q$6,IFERROR(MATCH($B$3,DEFAULTS!$N$2:$Q$2,0)+1,2),0),1))*(1+IF(B12="Box",$AY$3,$AY$4)),0) -> 0 | AW12: =IFERROR((AM12/1000)*R12*1*(1+IF(B12="Box",$AY$3,$AY$4)),0) -> 0 | AX12: =IFERROR(SUM(AS12:AW12),0) -> 0 | AY12: =IFERROR(AX12/(1+IF(B12="Box",$AY$3,$AY$4)),0) -> 0 | AZ12: =IFERROR(AS12*AN12+AT12*AO12+AU12*AP12+AV12*AQ12+AW12*AR12,0) -> 0 | BA12: =IFERROR(AX12*IF(B12="Box",$BA$3,$BA$4),0) -> 0 | BJ12: =IFERROR(SUM(AZ12:BI12)*$BJ$3,0) -> 0 | BK12: =IFERROR(AY12*IFERROR(IF($BK$4="",VLOOKUP(E12,DEFAULTS!$S$3:$V$20,IFERROR(MATCH($B$3,DEFAULTS!$T$3:$V$3,0)+1,2),0),$BK$4),0),0) -> 0 | BL12: =IFERROR(SUM(AZ12:BK12),0) -> 0 | BM12: =IFERROR(IF(B12="Box",$BM$3,$BM$4),0) -> 0.02 | BN12: =IFERROR(BL12*BM12,0) -> 0 | BO12: =IFERROR(MROUND(BL12+BN12,0.05),"") -> 0 | BP12: =IFERROR(BO12/AY12,"") | BQ12: =IFERROR(ROUND(J12*1100/AX12,-2),"") | BS12: =IF(B12="","",1) | BT12: =IFERROR(MROUND(BO12*BS12,0.05),"")
A13: =IF(B13="","",IF(B13="Box",COUNTIF($B$7:B13,"Box"),TEXT(COUNTIF($B$7:B13,"Box"),"0")&IF(B13="Plate","a",IF(B13="Part-L","b",IF(B13="Part-W","c",""))))) | F13: =IF(OR(B13="",B13="Box"),"",IF(B13="Plate",IFERROR(LOOKUP(2,1/(B$7:B12="Box"),F$7:F12)-5,""),"")) | G13: =IF(OR(B13="",B13="Box"),"",IF(B13="Plate",IFERROR(LOOKUP(2,1/(B$7:B12="Box"),G$7:G12)-5,""),IF(OR(B13="Part-L",B13="Part-W"),IFERROR(LOOKUP(2,1/(B$7:B12="Box"),H$7:H12)-15,""),""))) | L13: =IFERROR(INDEX(DEFAULTS!$E:$E,MATCH(I13,DEFAULTS!$A:$A,0)),"") | M13: =IFERROR(INDEX(DEFAULTS!$F:$F,MATCH(I13,DEFAULTS!$A:$A,0)),"") | N13: =IFERROR(INDEX(DEFAULTS!$G:$G,MATCH(I13,DEFAULTS!$A:$A,0)),"") | O13: =IFERROR(INDEX(DEFAULTS!$H:$H,MATCH(I13,DEFAULTS!$A:$A,0)),"") | P13: =IFERROR(IF(OR(I13="Board",I13="PP"),F13*K13+IF(J13=5,N13,L13),IF(I13="HRSC-L",(G13/2+H13)*K13+IF(J13=5,N13,L13),IF(I13="HRSC-R",(G13/2+H13)*K13+IF(J13=5,N13,L13),IF(I13="HRSC-O",H13*K13+IF(J13=5,N13,L13),(G13+H13)*K13+IF(J13=5,N13,L13))))),"") | Q13: =IFERROR(IF(OR(I13="Board",I13="PP"),G13+IF(J13=5,O13,M13),(F13+G13)*2+IF(J13=5,O13,M13)),"") | R13: =IFERROR(P13*Q13/1000000/K13,"") | T13: =IFERROR(AE13+AG13*IF(AB13="",1,IFERROR(VLOOKUP(AB13,DEFAULTS!$M$3:$Q$6,IFERROR(MATCH($B$3,DEFAULTS!$N$2:$Q$2,0)+1,2),0),1))+AI13+AK13*IF(AC13="",1,IFERROR(VLOOKUP(AC13,DEFAULTS!$M$3:$Q$6,IFERROR(MATCH($B$3,DEFAULTS!$N$2:$Q$2,0)+1,2),0),1))+AM13,"") -> 0 | V13: =IFERROR(IF(IFERROR(VALUE(LEFT(AD13,2)),0)=35,33,IFERROR(VALUE(LEFT(AD13,2)),0))*AE13/1000+IF(IFERROR(VALUE(LEFT(AF13,2)),0)=35,33,IFERROR(VALUE(LEFT(AF13,2)),0))*AG13*$V$4/1000+IF(IFERROR(VALUE(LEFT(AH13,2)),0)=35,33,IFERROR(VALUE(LEFT(AH13,2)),0))*AI13/1000+IF(IFERROR(VALUE(LEFT(AJ13,2)),0)=35,33,IFERROR(VALUE(LEFT(AJ13,2)),0))*AK13*$V$4/1000+IF(IFERROR(VALUE(LEFT(AL13,2)),0)=35,33,IFERROR(VALUE(LEFT(AL13,2)),0))*AM13/1000,"") -> 0 | AA13: =IFERROR(AY13*0.98*1000,0) -> 0 | AN13: =IFERROR(VLOOKUP(AD13,'RATE MASTER'!$A:$G,7,0)+IFERROR(VLOOKUP(AE13,'RATE MASTER'!$K$7:$M$10,3,1),0),"") | AO13: =IFERROR(VLOOKUP(AF13,'RATE MASTER'!$A:$G,7,0)+IFERROR(VLOOKUP(AG13,'RATE MASTER'!$K$7:$M$10,3,1),0),"") | AP13: =IFERROR(VLOOKUP(AH13,'RATE MASTER'!$A:$G,7,0)+IFERROR(VLOOKUP(AI13,'RATE MASTER'!$K$7:$M$10,3,1),0),"") | AQ13: =IFERROR(VLOOKUP(AJ13,'RATE MASTER'!$A:$G,7,0)+IFERROR(VLOOKUP(AK13,'RATE MASTER'!$K$7:$M$10,3,1),0),"") | AR13: =IFERROR(VLOOKUP(AL13,'RATE MASTER'!$A:$G,7,0)+IFERROR(VLOOKUP(AM13,'RATE MASTER'!$K$7:$M$10,3,1),0),"") | AS13: =IFERROR((AE13/1000)*R13*1*(1+IF(B13="Box",$AY$3,$AY$4)),0) -> 0 | AT13: =IFERROR((AG13/1000)*R13*IF(AB13="",1,IFERROR(VLOOKUP(AB13,DEFAULTS!$M$3:$Q$6,IFERROR(MATCH($B$3,DEFAULTS!$N$2:$Q$2,0)+1,2),0),1))*(1+IF(B13="Box",$AY$3,$AY$4)),0) -> 0 | AU13: =IFERROR((AI13/1000)*R13*1*(1+IF(B13="Box",$AY$3,$AY$4)),0) -> 0 | AV13: =IFERROR((AK13/1000)*R13*IF(AC13="",1,IFERROR(VLOOKUP(AC13,DEFAULTS!$M$3:$Q$6,IFERROR(MATCH($B$3,DEFAULTS!$N$2:$Q$2,0)+1,2),0),1))*(1+IF(B13="Box",$AY$3,$AY$4)),0) -> 0 | AW13: =IFERROR((AM13/1000)*R13*1*(1+IF(B13="Box",$AY$3,$AY$4)),0) -> 0 | AX13: =IFERROR(SUM(AS13:AW13),0) -> 0 | AY13: =IFERROR(AX13/(1+IF(B13="Box",$AY$3,$AY$4)),0) -> 0 | AZ13: =IFERROR(AS13*AN13+AT13*AO13+AU13*AP13+AV13*AQ13+AW13*AR13,0) -> 0 | BA13: =IFERROR(AX13*IF(B13="Box",$BA$3,$BA$4),0) -> 0 | BJ13: =IFERROR(SUM(AZ13:BI13)*$BJ$3,0) -> 0 | BK13: =IFERROR(AY13*IFERROR(IF($BK$4="",VLOOKUP(E13,DEFAULTS!$S$3:$V$20,IFERROR(MATCH($B$3,DEFAULTS!$T$3:$V$3,0)+1,2),0),$BK$4),0),0) -> 0 | BL13: =IFERROR(SUM(AZ13:BK13),0) -> 0 | BM13: =IFERROR(IF(B13="Box",$BM$3,$BM$4),0) -> 0.02 | BN13: =IFERROR(BL13*BM13,0) -> 0 | BO13: =IFERROR(MROUND(BL13+BN13,0.05),"") -> 0 | BP13: =IFERROR(BO13/AY13,"") | BQ13: =IFERROR(ROUND(J13*1100/AX13,-2),"") | BS13: =IF(B13="","",1) | BT13: =IFERROR(MROUND(BO13*BS13,0.05),"")
A14: =IF(B14="","",IF(B14="Box",COUNTIF($B$7:B14,"Box"),TEXT(COUNTIF($B$7:B14,"Box"),"0")&IF(B14="Plate","a",IF(B14="Part-L","b",IF(B14="Part-W","c",""))))) | F14: =IF(OR(B14="",B14="Box"),"",IF(B14="Plate",IFERROR(LOOKUP(2,1/(B$7:B13="Box"),F$7:F13)-5,""),"")) | G14: =IF(OR(B14="",B14="Box"),"",IF(B14="Plate",IFERROR(LOOKUP(2,1/(B$7:B13="Box"),G$7:G13)-5,""),IF(OR(B14="Part-L",B14="Part-W"),IFERROR(LOOKUP(2,1/(B$7:B13="Box"),H$7:H13)-15,""),""))) | L14: =IFERROR(INDEX(DEFAULTS!$E:$E,MATCH(I14,DEFAULTS!$A:$A,0)),"") | M14: =IFERROR(INDEX(DEFAULTS!$F:$F,MATCH(I14,DEFAULTS!$A:$A,0)),"") | N14: =IFERROR(INDEX(DEFAULTS!$G:$G,MATCH(I14,DEFAULTS!$A:$A,0)),"") | O14: =IFERROR(INDEX(DEFAULTS!$H:$H,MATCH(I14,DEFAULTS!$A:$A,0)),"") | P14: =IFERROR(IF(OR(I14="Board",I14="PP"),F14*K14+IF(J14=5,N14,L14),IF(I14="HRSC-L",(G14/2+H14)*K14+IF(J14=5,N14,L14),IF(I14="HRSC-R",(G14/2+H14)*K14+IF(J14=5,N14,L14),IF(I14="HRSC-O",H14*K14+IF(J14=5,N14,L14),(G14+H14)*K14+IF(J14=5,N14,L14))))),"") | Q14: =IFERROR(IF(OR(I14="Board",I14="PP"),G14+IF(J14=5,O14,M14),(F14+G14)*2+IF(J14=5,O14,M14)),"") | R14: =IFERROR(P14*Q14/1000000/K14,"") | T14: =IFERROR(AE14+AG14*IF(AB14="",1,IFERROR(VLOOKUP(AB14,DEFAULTS!$M$3:$Q$6,IFERROR(MATCH($B$3,DEFAULTS!$N$2:$Q$2,0)+1,2),0),1))+AI14+AK14*IF(AC14="",1,IFERROR(VLOOKUP(AC14,DEFAULTS!$M$3:$Q$6,IFERROR(MATCH($B$3,DEFAULTS!$N$2:$Q$2,0)+1,2),0),1))+AM14,"") -> 0 | V14: =IFERROR(IF(IFERROR(VALUE(LEFT(AD14,2)),0)=35,33,IFERROR(VALUE(LEFT(AD14,2)),0))*AE14/1000+IF(IFERROR(VALUE(LEFT(AF14,2)),0)=35,33,IFERROR(VALUE(LEFT(AF14,2)),0))*AG14*$V$4/1000+IF(IFERROR(VALUE(LEFT(AH14,2)),0)=35,33,IFERROR(VALUE(LEFT(AH14,2)),0))*AI14/1000+IF(IFERROR(VALUE(LEFT(AJ14,2)),0)=35,33,IFERROR(VALUE(LEFT(AJ14,2)),0))*AK14*$V$4/1000+IF(IFERROR(VALUE(LEFT(AL14,2)),0)=35,33,IFERROR(VALUE(LEFT(AL14,2)),0))*AM14/1000,"") -> 0 | AA14: =IFERROR(AY14*0.98*1000,0) -> 0 | AN14: =IFERROR(VLOOKUP(AD14,'RATE MASTER'!$A:$G,7,0)+IFERROR(VLOOKUP(AE14,'RATE MASTER'!$K$7:$M$10,3,1),0),"") | AO14: =IFERROR(VLOOKUP(AF14,'RATE MASTER'!$A:$G,7,0)+IFERROR(VLOOKUP(AG14,'RATE MASTER'!$K$7:$M$10,3,1),0),"") | AP14: =IFERROR(VLOOKUP(AH14,'RATE MASTER'!$A:$G,7,0)+IFERROR(VLOOKUP(AI14,'RATE MASTER'!$K$7:$M$10,3,1),0),"") | AQ14: =IFERROR(VLOOKUP(AJ14,'RATE MASTER'!$A:$G,7,0)+IFERROR(VLOOKUP(AK14,'RATE MASTER'!$K$7:$M$10,3,1),0),"") | AR14: =IFERROR(VLOOKUP(AL14,'RATE MASTER'!$A:$G,7,0)+IFERROR(VLOOKUP(AM14,'RATE MASTER'!$K$7:$M$10,3,1),0),"") | AS14: =IFERROR((AE14/1000)*R14*1*(1+IF(B14="Box",$AY$3,$AY$4)),0) -> 0 | AT14: =IFERROR((AG14/1000)*R14*IF(AB14="",1,IFERROR(VLOOKUP(AB14,DEFAULTS!$M$3:$Q$6,IFERROR(MATCH($B$3,DEFAULTS!$N$2:$Q$2,0)+1,2),0),1))*(1+IF(B14="Box",$AY$3,$AY$4)),0) -> 0 | AU14: =IFERROR((AI14/1000)*R14*1*(1+IF(B14="Box",$AY$3,$AY$4)),0) -> 0 | AV14: =IFERROR((AK14/1000)*R14*IF(AC14="",1,IFERROR(VLOOKUP(AC14,DEFAULTS!$M$3:$Q$6,IFERROR(MATCH($B$3,DEFAULTS!$N$2:$Q$2,0)+1,2),0),1))*(1+IF(B14="Box",$AY$3,$AY$4)),0) -> 0 | AW14: =IFERROR((AM14/1000)*R14*1*(1+IF(B14="Box",$AY$3,$AY$4)),0) -> 0 | AX14: =IFERROR(SUM(AS14:AW14),0) -> 0 | AY14: =IFERROR(AX14/(1+IF(B14="Box",$AY$3,$AY$4)),0) -> 0 | AZ14: =IFERROR(AS14*AN14+AT14*AO14+AU14*AP14+AV14*AQ14+AW14*AR14,0) -> 0 | BA14: =IFERROR(AX14*IF(B14="Box",$BA$3,$BA$4),0) -> 0 | BJ14: =IFERROR(SUM(AZ14:BI14)*$BJ$3,0) -> 0 | BK14: =IFERROR(AY14*IFERROR(IF($BK$4="",VLOOKUP(E14,DEFAULTS!$S$3:$V$20,IFERROR(MATCH($B$3,DEFAULTS!$T$3:$V$3,0)+1,2),0),$BK$4),0),0) -> 0 | BL14: =IFERROR(SUM(AZ14:BK14),0) -> 0 | BM14: =IFERROR(IF(B14="Box",$BM$3,$BM$4),0) -> 0.02 | BN14: =IFERROR(BL14*BM14,0) -> 0 | BO14: =IFERROR(MROUND(BL14+BN14,0.05),"") -> 0 | BP14: =IFERROR(BO14/AY14,"") | BQ14: =IFERROR(ROUND(J14*1100/AX14,-2),"") | BS14: =IF(B14="","",1) | BT14: =IFERROR(MROUND(BO14*BS14,0.05),"")
A15: =IF(B15="","",IF(B15="Box",COUNTIF($B$7:B15,"Box"),TEXT(COUNTIF($B$7:B15,"Box"),"0")&IF(B15="Plate","a",IF(B15="Part-L","b",IF(B15="Part-W","c",""))))) | F15: =IF(OR(B15="",B15="Box"),"",IF(B15="Plate",IFERROR(LOOKUP(2,1/(B$7:B14="Box"),F$7:F14)-5,""),"")) | G15: =IF(OR(B15="",B15="Box"),"",IF(B15="Plate",IFERROR(LOOKUP(2,1/(B$7:B14="Box"),G$7:G14)-5,""),IF(OR(B15="Part-L",B15="Part-W"),IFERROR(LOOKUP(2,1/(B$7:B14="Box"),H$7:H14)-15,""),""))) | L15: =IFERROR(INDEX(DEFAULTS!$E:$E,MATCH(I15,DEFAULTS!$A:$A,0)),"") | M15: =IFERROR(INDEX(DEFAULTS!$F:$F,MATCH(I15,DEFAULTS!$A:$A,0)),"") | N15: =IFERROR(INDEX(DEFAULTS!$G:$G,MATCH(I15,DEFAULTS!$A:$A,0)),"") | O15: =IFERROR(INDEX(DEFAULTS!$H:$H,MATCH(I15,DEFAULTS!$A:$A,0)),"") | P15: =IFERROR(IF(OR(I15="Board",I15="PP"),F15*K15+IF(J15=5,N15,L15),IF(I15="HRSC-L",(G15/2+H15)*K15+IF(J15=5,N15,L15),IF(I15="HRSC-R",(G15/2+H15)*K15+IF(J15=5,N15,L15),IF(I15="HRSC-O",H15*K15+IF(J15=5,N15,L15),(G15+H15)*K15+IF(J15=5,N15,L15))))),"") | Q15: =IFERROR(IF(OR(I15="Board",I15="PP"),G15+IF(J15=5,O15,M15),(F15+G15)*2+IF(J15=5,O15,M15)),"") | R15: =IFERROR(P15*Q15/1000000/K15,"") | T15: =IFERROR(AE15+AG15*IF(AB15="",1,IFERROR(VLOOKUP(AB15,DEFAULTS!$M$3:$Q$6,IFERROR(MATCH($B$3,DEFAULTS!$N$2:$Q$2,0)+1,2),0),1))+AI15+AK15*IF(AC15="",1,IFERROR(VLOOKUP(AC15,DEFAULTS!$M$3:$Q$6,IFERROR(MATCH($B$3,DEFAULTS!$N$2:$Q$2,0)+1,2),0),1))+AM15,"") -> 0 | V15: =IFERROR(IF(IFERROR(VALUE(LEFT(AD15,2)),0)=35,33,IFERROR(VALUE(LEFT(AD15,2)),0))*AE15/1000+IF(IFERROR(VALUE(LEFT(AF15,2)),0)=35,33,IFERROR(VALUE(LEFT(AF15,2)),0))*AG15*$V$4/1000+IF(IFERROR(VALUE(LEFT(AH15,2)),0)=35,33,IFERROR(VALUE(LEFT(AH15,2)),0))*AI15/1000+IF(IFERROR(VALUE(LEFT(AJ15,2)),0)=35,33,IFERROR(VALUE(LEFT(AJ15,2)),0))*AK15*$V$4/1000+IF(IFERROR(VALUE(LEFT(AL15,2)),0)=35,33,IFERROR(VALUE(LEFT(AL15,2)),0))*AM15/1000,"") -> 0 | AA15: =IFERROR(AY15*0.98*1000,0) -> 0 | AN15: =IFERROR(VLOOKUP(AD15,'RATE MASTER'!$A:$G,7,0)+IFERROR(VLOOKUP(AE15,'RATE MASTER'!$K$7:$M$10,3,1),0),"") | AO15: =IFERROR(VLOOKUP(AF15,'RATE MASTER'!$A:$G,7,0)+IFERROR(VLOOKUP(AG15,'RATE MASTER'!$K$7:$M$10,3,1),0),"") | AP15: =IFERROR(VLOOKUP(AH15,'RATE MASTER'!$A:$G,7,0)+IFERROR(VLOOKUP(AI15,'RATE MASTER'!$K$7:$M$10,3,1),0),"") | AQ15: =IFERROR(VLOOKUP(AJ15,'RATE MASTER'!$A:$G,7,0)+IFERROR(VLOOKUP(AK15,'RATE MASTER'!$K$7:$M$10,3,1),0),"") | AR15: =IFERROR(VLOOKUP(AL15,'RATE MASTER'!$A:$G,7,0)+IFERROR(VLOOKUP(AM15,'RATE MASTER'!$K$7:$M$10,3,1),0),"") | AS15: =IFERROR((AE15/1000)*R15*1*(1+IF(B15="Box",$AY$3,$AY$4)),0) -> 0 | AT15: =IFERROR((AG15/1000)*R15*IF(AB15="",1,IFERROR(VLOOKUP(AB15,DEFAULTS!$M$3:$Q$6,IFERROR(MATCH($B$3,DEFAULTS!$N$2:$Q$2,0)+1,2),0),1))*(1+IF(B15="Box",$AY$3,$AY$4)),0) -> 0 | AU15: =IFERROR((AI15/1000)*R15*1*(1+IF(B15="Box",$AY$3,$AY$4)),0) -> 0 | AV15: =IFERROR((AK15/1000)*R15*IF(AC15="",1,IFERROR(VLOOKUP(AC15,DEFAULTS!$M$3:$Q$6,IFERROR(MATCH($B$3,DEFAULTS!$N$2:$Q$2,0)+1,2),0),1))*(1+IF(B15="Box",$AY$3,$AY$4)),0) -> 0 | AW15: =IFERROR((AM15/1000)*R15*1*(1+IF(B15="Box",$AY$3,$AY$4)),0) -> 0 | AX15: =IFERROR(SUM(AS15:AW15),0) -> 0 | AY15: =IFERROR(AX15/(1+IF(B15="Box",$AY$3,$AY$4)),0) -> 0 | AZ15: =IFERROR(AS15*AN15+AT15*AO15+AU15*AP15+AV15*AQ15+AW15*AR15,0) -> 0 | BA15: =IFERROR(AX15*IF(B15="Box",$BA$3,$BA$4),0) -> 0 | BJ15: =IFERROR(SUM(AZ15:BI15)*$BJ$3,0) -> 0 | BK15: =IFERROR(AY15*IFERROR(IF($BK$4="",VLOOKUP(E15,DEFAULTS!$S$3:$V$20,IFERROR(MATCH($B$3,DEFAULTS!$T$3:$V$3,0)+1,2),0),$BK$4),0),0) -> 0 | BL15: =IFERROR(SUM(AZ15:BK15),0) -> 0 | BM15: =IFERROR(IF(B15="Box",$BM$3,$BM$4),0) -> 0.02 | BN15: =IFERROR(BL15*BM15,0) -> 0 | BO15: =IFERROR(MROUND(BL15+BN15,0.05),"") -> 0 | BP15: =IFERROR(BO15/AY15,"") | BQ15: =IFERROR(ROUND(J15*1100/AX15,-2),"") | BS15: =IF(B15="","",1) | BT15: =IFERROR(MROUND(BO15*BS15,0.05),"")
A16: =IF(B16="","",IF(B16="Box",COUNTIF($B$7:B16,"Box"),TEXT(COUNTIF($B$7:B16,"Box"),"0")&IF(B16="Plate","a",IF(B16="Part-L","b",IF(B16="Part-W","c",""))))) | F16: =IF(OR(B16="",B16="Box"),"",IF(B16="Plate",IFERROR(LOOKUP(2,1/(B$7:B15="Box"),F$7:F15)-5,""),"")) | G16: =IF(OR(B16="",B16="Box"),"",IF(B16="Plate",IFERROR(LOOKUP(2,1/(B$7:B15="Box"),G$7:G15)-5,""),IF(OR(B16="Part-L",B16="Part-W"),IFERROR(LOOKUP(2,1/(B$7:B15="Box"),H$7:H15)-15,""),""))) | L16: =IFERROR(INDEX(DEFAULTS!$E:$E,MATCH(I16,DEFAULTS!$A:$A,0)),"") | M16: =IFERROR(INDEX(DEFAULTS!$F:$F,MATCH(I16,DEFAULTS!$A:$A,0)),"") | N16: =IFERROR(INDEX(DEFAULTS!$G:$G,MATCH(I16,DEFAULTS!$A:$A,0)),"") | O16: =IFERROR(INDEX(DEFAULTS!$H:$H,MATCH(I16,DEFAULTS!$A:$A,0)),"") | P16: =IFERROR(IF(OR(I16="Board",I16="PP"),F16*K16+IF(J16=5,N16,L16),IF(I16="HRSC-L",(G16/2+H16)*K16+IF(J16=5,N16,L16),IF(I16="HRSC-R",(G16/2+H16)*K16+IF(J16=5,N16,L16),IF(I16="HRSC-O",H16*K16+IF(J16=5,N16,L16),(G16+H16)*K16+IF(J16=5,N16,L16))))),"") | Q16: =IFERROR(IF(OR(I16="Board",I16="PP"),G16+IF(J16=5,O16,M16),(F16+G16)*2+IF(J16=5,O16,M16)),"") | R16: =IFERROR(P16*Q16/1000000/K16,"") | T16: =IFERROR(AE16+AG16*IF(AB16="",1,IFERROR(VLOOKUP(AB16,DEFAULTS!$M$3:$Q$6,IFERROR(MATCH($B$3,DEFAULTS!$N$2:$Q$2,0)+1,2),0),1))+AI16+AK16*IF(AC16="",1,IFERROR(VLOOKUP(AC16,DEFAULTS!$M$3:$Q$6,IFERROR(MATCH($B$3,DEFAULTS!$N$2:$Q$2,0)+1,2),0),1))+AM16,"") -> 0 | V16: =IFERROR(IF(IFERROR(VALUE(LEFT(AD16,2)),0)=35,33,IFERROR(VALUE(LEFT(AD16,2)),0))*AE16/1000+IF(IFERROR(VALUE(LEFT(AF16,2)),0)=35,33,IFERROR(VALUE(LEFT(AF16,2)),0))*AG16*$V$4/1000+IF(IFERROR(VALUE(LEFT(AH16,2)),0)=35,33,IFERROR(VALUE(LEFT(AH16,2)),0))*AI16/1000+IF(IFERROR(VALUE(LEFT(AJ16,2)),0)=35,33,IFERROR(VALUE(LEFT(AJ16,2)),0))*AK16*$V$4/1000+IF(IFERROR(VALUE(LEFT(AL16,2)),0)=35,33,IFERROR(VALUE(LEFT(AL16,2)),0))*AM16/1000,"") -> 0 | AA16: =IFERROR(AY16*0.98*1000,0) -> 0 | AN16: =IFERROR(VLOOKUP(AD16,'RATE MASTER'!$A:$G,7,0)+IFERROR(VLOOKUP(AE16,'RATE MASTER'!$K$7:$M$10,3,1),0),"") | AO16: =IFERROR(VLOOKUP(AF16,'RATE MASTER'!$A:$G,7,0)+IFERROR(VLOOKUP(AG16,'RATE MASTER'!$K$7:$M$10,3,1),0),"") | AP16: =IFERROR(VLOOKUP(AH16,'RATE MASTER'!$A:$G,7,0)+IFERROR(VLOOKUP(AI16,'RATE MASTER'!$K$7:$M$10,3,1),0),"") | AQ16: =IFERROR(VLOOKUP(AJ16,'RATE MASTER'!$A:$G,7,0)+IFERROR(VLOOKUP(AK16,'RATE MASTER'!$K$7:$M$10,3,1),0),"") | AR16: =IFERROR(VLOOKUP(AL16,'RATE MASTER'!$A:$G,7,0)+IFERROR(VLOOKUP(AM16,'RATE MASTER'!$K$7:$M$10,3,1),0),"") | AS16: =IFERROR((AE16/1000)*R16*1*(1+IF(B16="Box",$AY$3,$AY$4)),0) -> 0 | AT16: =IFERROR((AG16/1000)*R16*IF(AB16="",1,IFERROR(VLOOKUP(AB16,DEFAULTS!$M$3:$Q$6,IFERROR(MATCH($B$3,DEFAULTS!$N$2:$Q$2,0)+1,2),0),1))*(1+IF(B16="Box",$AY$3,$AY$4)),0) -> 0 | AU16: =IFERROR((AI16/1000)*R16*1*(1+IF(B16="Box",$AY$3,$AY$4)),0) -> 0 | AV16: =IFERROR((AK16/1000)*R16*IF(AC16="",1,IFERROR(VLOOKUP(AC16,DEFAULTS!$M$3:$Q$6,IFERROR(MATCH($B$3,DEFAULTS!$N$2:$Q$2,0)+1,2),0),1))*(1+IF(B16="Box",$AY$3,$AY$4)),0) -> 0 | AW16: =IFERROR((AM16/1000)*R16*1*(1+IF(B16="Box",$AY$3,$AY$4)),0) -> 0 | AX16: =IFERROR(SUM(AS16:AW16),0) -> 0 | AY16: =IFERROR(AX16/(1+IF(B16="Box",$AY$3,$AY$4)),0) -> 0 | AZ16: =IFERROR(AS16*AN16+AT16*AO16+AU16*AP16+AV16*AQ16+AW16*AR16,0) -> 0 | BA16: =IFERROR(AX16*IF(B16="Box",$BA$3,$BA$4),0) -> 0 | BJ16: =IFERROR(SUM(AZ16:BI16)*$BJ$3,0) -> 0 | BK16: =IFERROR(AY16*IFERROR(IF($BK$4="",VLOOKUP(E16,DEFAULTS!$S$3:$V$20,IFERROR(MATCH($B$3,DEFAULTS!$T$3:$V$3,0)+1,2),0),$BK$4),0),0) -> 0 | BL16: =IFERROR(SUM(AZ16:BK16),0) -> 0 | BM16: =IFERROR(IF(B16="Box",$BM$3,$BM$4),0) -> 0.02 | BN16: =IFERROR(BL16*BM16,0) -> 0 | BO16: =IFERROR(MROUND(BL16+BN16,0.05),"") -> 0 | BP16: =IFERROR(BO16/AY16,"") | BQ16: =IFERROR(ROUND(J16*1100/AX16,-2),"") | BS16: =IF(B16="","",1) | BT16: =IFERROR(MROUND(BO16*BS16,0.05),"")
A17: =IF(B17="","",IF(B17="Box",COUNTIF($B$7:B17,"Box"),TEXT(COUNTIF($B$7:B17,"Box"),"0")&IF(B17="Plate","a",IF(B17="Part-L","b",IF(B17="Part-W","c",""))))) | F17: =IF(OR(B17="",B17="Box"),"",IF(B17="Plate",IFERROR(LOOKUP(2,1/(B$7:B16="Box"),F$7:F16)-5,""),"")) | G17: =IF(OR(B17="",B17="Box"),"",IF(B17="Plate",IFERROR(LOOKUP(2,1/(B$7:B16="Box"),G$7:G16)-5,""),IF(OR(B17="Part-L",B17="Part-W"),IFERROR(LOOKUP(2,1/(B$7:B16="Box"),H$7:H16)-15,""),""))) | L17: =IFERROR(INDEX(DEFAULTS!$E:$E,MATCH(I17,DEFAULTS!$A:$A,0)),"") | M17: =IFERROR(INDEX(DEFAULTS!$F:$F,MATCH(I17,DEFAULTS!$A:$A,0)),"") | N17: =IFERROR(INDEX(DEFAULTS!$G:$G,MATCH(I17,DEFAULTS!$A:$A,0)),"") | O17: =IFERROR(INDEX(DEFAULTS!$H:$H,MATCH(I17,DEFAULTS!$A:$A,0)),"") | P17: =IFERROR(IF(OR(I17="Board",I17="PP"),F17*K17+IF(J17=5,N17,L17),IF(I17="HRSC-L",(G17/2+H17)*K17+IF(J17=5,N17,L17),IF(I17="HRSC-R",(G17/2+H17)*K17+IF(J17=5,N17,L17),IF(I17="HRSC-O",H17*K17+IF(J17=5,N17,L17),(G17+H17)*K17+IF(J17=5,N17,L17))))),"") | Q17: =IFERROR(IF(OR(I17="Board",I17="PP"),G17+IF(J17=5,O17,M17),(F17+G17)*2+IF(J17=5,O17,M17)),"") | R17: =IFERROR(P17*Q17/1000000/K17,"") | T17: =IFERROR(AE17+AG17*IF(AB17="",1,IFERROR(VLOOKUP(AB17,DEFAULTS!$M$3:$Q$6,IFERROR(MATCH($B$3,DEFAULTS!$N$2:$Q$2,0)+1,2),0),1))+AI17+AK17*IF(AC17="",1,IFERROR(VLOOKUP(AC17,DEFAULTS!$M$3:$Q$6,IFERROR(MATCH($B$3,DEFAULTS!$N$2:$Q$2,0)+1,2),0),1))+AM17,"") -> 0 | V17: =IFERROR(IF(IFERROR(VALUE(LEFT(AD17,2)),0)=35,33,IFERROR(VALUE(LEFT(AD17,2)),0))*AE17/1000+IF(IFERROR(VALUE(LEFT(AF17,2)),0)=35,33,IFERROR(VALUE(LEFT(AF17,2)),0))*AG17*$V$4/1000+IF(IFERROR(VALUE(LEFT(AH17,2)),0)=35,33,IFERROR(VALUE(LEFT(AH17,2)),0))*AI17/1000+IF(IFERROR(VALUE(LEFT(AJ17,2)),0)=35,33,IFERROR(VALUE(LEFT(AJ17,2)),0))*AK17*$V$4/1000+IF(IFERROR(VALUE(LEFT(AL17,2)),0)=35,33,IFERROR(VALUE(LEFT(AL17,2)),0))*AM17/1000,"") -> 0 | AA17: =IFERROR(AY17*0.98*1000,0) -> 0 | AN17: =IFERROR(VLOOKUP(AD17,'RATE MASTER'!$A:$G,7,0)+IFERROR(VLOOKUP(AE17,'RATE MASTER'!$K$7:$M$10,3,1),0),"") | AO17: =IFERROR(VLOOKUP(AF17,'RATE MASTER'!$A:$G,7,0)+IFERROR(VLOOKUP(AG17,'RATE MASTER'!$K$7:$M$10,3,1),0),"") | AP17: =IFERROR(VLOOKUP(AH17,'RATE MASTER'!$A:$G,7,0)+IFERROR(VLOOKUP(AI17,'RATE MASTER'!$K$7:$M$10,3,1),0),"") | AQ17: =IFERROR(VLOOKUP(AJ17,'RATE MASTER'!$A:$G,7,0)+IFERROR(VLOOKUP(AK17,'RATE MASTER'!$K$7:$M$10,3,1),0),"") | AR17: =IFERROR(VLOOKUP(AL17,'RATE MASTER'!$A:$G,7,0)+IFERROR(VLOOKUP(AM17,'RATE MASTER'!$K$7:$M$10,3,1),0),"") | AS17: =IFERROR((AE17/1000)*R17*1*(1+IF(B17="Box",$AY$3,$AY$4)),0) -> 0 | AT17: =IFERROR((AG17/1000)*R17*IF(AB17="",1,IFERROR(VLOOKUP(AB17,DEFAULTS!$M$3:$Q$6,IFERROR(MATCH($B$3,DEFAULTS!$N$2:$Q$2,0)+1,2),0),1))*(1+IF(B17="Box",$AY$3,$AY$4)),0) -> 0 | AU17: =IFERROR((AI17/1000)*R17*1*(1+IF(B17="Box",$AY$3,$AY$4)),0) -> 0 | AV17: =IFERROR((AK17/1000)*R17*IF(AC17="",1,IFERROR(VLOOKUP(AC17,DEFAULTS!$M$3:$Q$6,IFERROR(MATCH($B$3,DEFAULTS!$N$2:$Q$2,0)+1,2),0),1))*(1+IF(B17="Box",$AY$3,$AY$4)),0) -> 0 | AW17: =IFERROR((AM17/1000)*R17*1*(1+IF(B17="Box",$AY$3,$AY$4)),0) -> 0 | AX17: =IFERROR(SUM(AS17:AW17),0) -> 0 | AY17: =IFERROR(AX17/(1+IF(B17="Box",$AY$3,$AY$4)),0) -> 0 | AZ17: =IFERROR(AS17*AN17+AT17*AO17+AU17*AP17+AV17*AQ17+AW17*AR17,0) -> 0 | BA17: =IFERROR(AX17*IF(B17="Box",$BA$3,$BA$4),0) -> 0 | BJ17: =IFERROR(SUM(AZ17:BI17)*$BJ$3,0) -> 0 | BK17: =IFERROR(AY17*IFERROR(IF($BK$4="",VLOOKUP(E17,DEFAULTS!$S$3:$V$20,IFERROR(MATCH($B$3,DEFAULTS!$T$3:$V$3,0)+1,2),0),$BK$4),0),0) -> 0 | BL17: =IFERROR(SUM(AZ17:BK17),0) -> 0 | BM17: =IFERROR(IF(B17="Box",$BM$3,$BM$4),0) -> 0.02 | BN17: =IFERROR(BL17*BM17,0) -> 0 | BO17: =IFERROR(MROUND(BL17+BN17,0.05),"") -> 0 | BP17: =IFERROR(BO17/AY17,"") | BQ17: =IFERROR(ROUND(J17*1100/AX17,-2),"") | BS17: =IF(B17="","",1) | BT17: =IFERROR(MROUND(BO17*BS17,0.05),"")
A18: =IF(B18="","",IF(B18="Box",COUNTIF($B$7:B18,"Box"),TEXT(COUNTIF($B$7:B18,"Box"),"0")&IF(B18="Plate","a",IF(B18="Part-L","b",IF(B18="Part-W","c",""))))) | F18: =IF(OR(B18="",B18="Box"),"",IF(B18="Plate",IFERROR(LOOKUP(2,1/(B$7:B17="Box"),F$7:F17)-5,""),"")) | G18: =IF(OR(B18="",B18="Box"),"",IF(B18="Plate",IFERROR(LOOKUP(2,1/(B$7:B17="Box"),G$7:G17)-5,""),IF(OR(B18="Part-L",B18="Part-W"),IFERROR(LOOKUP(2,1/(B$7:B17="Box"),H$7:H17)-15,""),""))) | L18: =IFERROR(INDEX(DEFAULTS!$E:$E,MATCH(I18,DEFAULTS!$A:$A,0)),"") | M18: =IFERROR(INDEX(DEFAULTS!$F:$F,MATCH(I18,DEFAULTS!$A:$A,0)),"") | N18: =IFERROR(INDEX(DEFAULTS!$G:$G,MATCH(I18,DEFAULTS!$A:$A,0)),"") | O18: =IFERROR(INDEX(DEFAULTS!$H:$H,MATCH(I18,DEFAULTS!$A:$A,0)),"") | P18: =IFERROR(IF(OR(I18="Board",I18="PP"),F18*K18+IF(J18=5,N18,L18),IF(I18="HRSC-L",(G18/2+H18)*K18+IF(J18=5,N18,L18),IF(I18="HRSC-R",(G18/2+H18)*K18+IF(J18=5,N18,L18),IF(I18="HRSC-O",H18*K18+IF(J18=5,N18,L18),(G18+H18)*K18+IF(J18=5,N18,L18))))),"") | Q18: =IFERROR(IF(OR(I18="Board",I18="PP"),G18+IF(J18=5,O18,M18),(F18+G18)*2+IF(J18=5,O18,M18)),"") | R18: =IFERROR(P18*Q18/1000000/K18,"") | T18: =IFERROR(AE18+AG18*IF(AB18="",1,IFERROR(VLOOKUP(AB18,DEFAULTS!$M$3:$Q$6,IFERROR(MATCH($B$3,DEFAULTS!$N$2:$Q$2,0)+1,2),0),1))+AI18+AK18*IF(AC18="",1,IFERROR(VLOOKUP(AC18,DEFAULTS!$M$3:$Q$6,IFERROR(MATCH($B$3,DEFAULTS!$N$2:$Q$2,0)+1,2),0),1))+AM18,"") -> 0 | V18: =IFERROR(IF(IFERROR(VALUE(LEFT(AD18,2)),0)=35,33,IFERROR(VALUE(LEFT(AD18,2)),0))*AE18/1000+IF(IFERROR(VALUE(LEFT(AF18,2)),0)=35,33,IFERROR(VALUE(LEFT(AF18,2)),0))*AG18*$V$4/1000+IF(IFERROR(VALUE(LEFT(AH18,2)),0)=35,33,IFERROR(VALUE(LEFT(AH18,2)),0))*AI18/1000+IF(IFERROR(VALUE(LEFT(AJ18,2)),0)=35,33,IFERROR(VALUE(LEFT(AJ18,2)),0))*AK18*$V$4/1000+IF(IFERROR(VALUE(LEFT(AL18,2)),0)=35,33,IFERROR(VALUE(LEFT(AL18,2)),0))*AM18/1000,"") -> 0 | AA18: =IFERROR(AY18*0.98*1000,0) -> 0 | AN18: =IFERROR(VLOOKUP(AD18,'RATE MASTER'!$A:$G,7,0)+IFERROR(VLOOKUP(AE18,'RATE MASTER'!$K$7:$M$10,3,1),0),"") | AO18: =IFERROR(VLOOKUP(AF18,'RATE MASTER'!$A:$G,7,0)+IFERROR(VLOOKUP(AG18,'RATE MASTER'!$K$7:$M$10,3,1),0),"") | AP18: =IFERROR(VLOOKUP(AH18,'RATE MASTER'!$A:$G,7,0)+IFERROR(VLOOKUP(AI18,'RATE MASTER'!$K$7:$M$10,3,1),0),"") | AQ18: =IFERROR(VLOOKUP(AJ18,'RATE MASTER'!$A:$G,7,0)+IFERROR(VLOOKUP(AK18,'RATE MASTER'!$K$7:$M$10,3,1),0),"") | AR18: =IFERROR(VLOOKUP(AL18,'RATE MASTER'!$A:$G,7,0)+IFERROR(VLOOKUP(AM18,'RATE MASTER'!$K$7:$M$10,3,1),0),"") | AS18: =IFERROR((AE18/1000)*R18*1*(1+IF(B18="Box",$AY$3,$AY$4)),0) -> 0 | AT18: =IFERROR((AG18/1000)*R18*IF(AB18="",1,IFERROR(VLOOKUP(AB18,DEFAULTS!$M$3:$Q$6,IFERROR(MATCH($B$3,DEFAULTS!$N$2:$Q$2,0)+1,2),0),1))*(1+IF(B18="Box",$AY$3,$AY$4)),0) -> 0 | AU18: =IFERROR((AI18/1000)*R18*1*(1+IF(B18="Box",$AY$3,$AY$4)),0) -> 0 | AV18: =IFERROR((AK18/1000)*R18*IF(AC18="",1,IFERROR(VLOOKUP(AC18,DEFAULTS!$M$3:$Q$6,IFERROR(MATCH($B$3,DEFAULTS!$N$2:$Q$2,0)+1,2),0),1))*(1+IF(B18="Box",$AY$3,$AY$4)),0) -> 0 | AW18: =IFERROR((AM18/1000)*R18*1*(1+IF(B18="Box",$AY$3,$AY$4)),0) -> 0 | AX18: =IFERROR(SUM(AS18:AW18),0) -> 0 | AY18: =IFERROR(AX18/(1+IF(B18="Box",$AY$3,$AY$4)),0) -> 0 | AZ18: =IFERROR(AS18*AN18+AT18*AO18+AU18*AP18+AV18*AQ18+AW18*AR18,0) -> 0 | BA18: =IFERROR(AX18*IF(B18="Box",$BA$3,$BA$4),0) -> 0 | BJ18: =IFERROR(SUM(AZ18:BI18)*$BJ$3,0) -> 0 | BK18: =IFERROR(AY18*IFERROR(IF($BK$4="",VLOOKUP(E18,DEFAULTS!$S$3:$V$20,IFERROR(MATCH($B$3,DEFAULTS!$T$3:$V$3,0)+1,2),0),$BK$4),0),0) -> 0 | BL18: =IFERROR(SUM(AZ18:BK18),0) -> 0 | BM18: =IFERROR(IF(B18="Box",$BM$3,$BM$4),0) -> 0.02 | BN18: =IFERROR(BL18*BM18,0) -> 0 | BO18: =IFERROR(MROUND(BL18+BN18,0.05),"") -> 0 | BP18: =IFERROR(BO18/AY18,"") | BQ18: =IFERROR(ROUND(J18*1100/AX18,-2),"") | BS18: =IF(B18="","",1) | BT18: =IFERROR(MROUND(BO18*BS18,0.05),"")
